2020-09-30 16:23:32,663 ERROR 60251 nodejs.ClusterClientNoResponseError: client no response in 350197ms exceeding maxIdleTime 60000ms, maybe the connection is close on other side.
    at Timeout._onTimeout (/Users/lxd/Desktop/egg-example/node_modules/cluster-client/lib/leader.js:77:23)
    at listOnTimeout (internal/timers.js:549:17)
    at processTimers (internal/timers.js:492:7)
name: "ClusterClientNoResponseError"
pid: 60251
hostname: lxddeMacBook-Pro.local

2020-09-30 17:04:07,157 ERROR 91925 [-/192.168.7.50/-/6ms GET /gannt/created] nodejs.ReferenceError: params is not defined
    at GanntController.created (/Users/lxd/Desktop/egg-example/app/controller/gannt.js:49:46)
    at Object.callFn (/Users/lxd/Desktop/egg-example/node_modules/egg-core/lib/utils/index.js:44:21)
    at Object.classControllerMiddleware (/Users/lxd/Desktop/egg-example/node_modules/egg-core/lib/loader/mixin/controller.js:87:20)
    at Object.callFn (/Users/lxd/Desktop/egg-example/node_modules/@eggjs/router/lib/utils.js:12:21)
    at wrappedController (/Users/lxd/Desktop/egg-example/node_modules/@eggjs/router/lib/egg_router.js:322:18)
    at dispatch (/Users/lxd/Desktop/egg-example/node_modules/koa-compose/index.js:44:32)
    at next (/Users/lxd/Desktop/egg-example/node_modules/koa-compose/index.js:45:18)
    at /Users/lxd/Desktop/egg-example/node_modules/@eggjs/router/lib/router.js:190:18
    at dispatch (/Users/lxd/Desktop/egg-example/node_modules/koa-compose/index.js:44:32)
    at /Users/lxd/Desktop/egg-example/node_modules/koa-compose/index.js:36:12

pid: 91925
hostname: lxddeMacBook-Pro.local

2020-09-30 17:04:58,542 ERROR 91972 [-/192.168.7.50/-/12ms GET /gannt/created] nodejs.SequelizeDatabaseError: Field 'label' doesn't have a default value
    at Query.formatError (/Users/lxd/Desktop/egg-example/node_modules/sequelize/lib/dialects/mysql/query.js:239:16)
    at Query.run (/Users/lxd/Desktop/egg-example/node_modules/sequelize/lib/dialects/mysql/query.js:54:18)
    at processTicksAndRejections (internal/process/task_queues.js:97:5)
name: "SequelizeDatabaseError"
parent: {"code":"ER_NO_DEFAULT_FOR_FIELD","errno":1364,"sqlState":"HY000","sqlMessage":"Field 'label' doesn't have a default value","sql":"INSERT INTO `gannt` (`id`) VALUES (DEFAULT);"}
original: {"code":"ER_NO_DEFAULT_FOR_FIELD","errno":1364,"sqlState":"HY000","sqlMessage":"Field 'label' doesn't have a default value","sql":"INSERT INTO `gannt` (`id`) VALUES (DEFAULT);"}
sql: "INSERT INTO `gannt` (`id`) VALUES (DEFAULT);"
parameters: undefined
pid: 91972
hostname: lxddeMacBook-Pro.local

2020-09-30 17:07:30,511 ERROR 92123 [-/192.168.7.50/-/17ms POST /gannt/created] nodejs.SequelizeDatabaseError: Field 'label' doesn't have a default value
    at Query.formatError (/Users/lxd/Desktop/egg-example/node_modules/sequelize/lib/dialects/mysql/query.js:239:16)
    at Query.run (/Users/lxd/Desktop/egg-example/node_modules/sequelize/lib/dialects/mysql/query.js:54:18)
    at processTicksAndRejections (internal/process/task_queues.js:97:5)
name: "SequelizeDatabaseError"
parent: {"code":"ER_NO_DEFAULT_FOR_FIELD","errno":1364,"sqlState":"HY000","sqlMessage":"Field 'label' doesn't have a default value","sql":"INSERT INTO `gannt` (`id`) VALUES (DEFAULT);"}
original: {"code":"ER_NO_DEFAULT_FOR_FIELD","errno":1364,"sqlState":"HY000","sqlMessage":"Field 'label' doesn't have a default value","sql":"INSERT INTO `gannt` (`id`) VALUES (DEFAULT);"}
sql: "INSERT INTO `gannt` (`id`) VALUES (DEFAULT);"
parameters: undefined
headers: {"Access-Control-Allow-Origin":"*","vary":"Origin"}
pid: 92123
hostname: lxddeMacBook-Pro.local

2020-09-30 17:08:04,973 ERROR 92123 [-/192.168.7.50/-/5ms POST /gannt/created] nodejs.SequelizeDatabaseError: Field 'label' doesn't have a default value
    at Query.formatError (/Users/lxd/Desktop/egg-example/node_modules/sequelize/lib/dialects/mysql/query.js:239:16)
    at Query.run (/Users/lxd/Desktop/egg-example/node_modules/sequelize/lib/dialects/mysql/query.js:54:18)
    at processTicksAndRejections (internal/process/task_queues.js:97:5)
name: "SequelizeDatabaseError"
parent: {"code":"ER_NO_DEFAULT_FOR_FIELD","errno":1364,"sqlState":"HY000","sqlMessage":"Field 'label' doesn't have a default value","sql":"INSERT INTO `gannt` (`id`) VALUES (DEFAULT);"}
original: {"code":"ER_NO_DEFAULT_FOR_FIELD","errno":1364,"sqlState":"HY000","sqlMessage":"Field 'label' doesn't have a default value","sql":"INSERT INTO `gannt` (`id`) VALUES (DEFAULT);"}
sql: "INSERT INTO `gannt` (`id`) VALUES (DEFAULT);"
parameters: undefined
headers: {"Access-Control-Allow-Origin":"*","vary":"Origin"}
pid: 92123
hostname: lxddeMacBook-Pro.local

2020-09-30 17:08:40,126 ERROR 92123 [-/192.168.7.50/-/5ms POST /gannt/created] nodejs.SequelizeDatabaseError: Incorrect integer value: '' for column 'start' at row 1
    at Query.formatError (/Users/lxd/Desktop/egg-example/node_modules/sequelize/lib/dialects/mysql/query.js:239:16)
    at Query.run (/Users/lxd/Desktop/egg-example/node_modules/sequelize/lib/dialects/mysql/query.js:54:18)
    at processTicksAndRejections (internal/process/task_queues.js:97:5)
name: "SequelizeDatabaseError"
parent: {"code":"ER_TRUNCATED_WRONG_VALUE_FOR_FIELD","errno":1366,"sqlState":"HY000","sqlMessage":"Incorrect integer value: '' for column 'start' at row 1","sql":"INSERT INTO `gannt` (`id`,`label`,`user`,`start`,`endDate`,`duration`,`percent`,`type`,`proType`,`risk`) VALUES (DEFAULT,?,?,?,?,?,?,?,?,?);","parameters":["asdf","","",null,1,10,"","",""]}
original: {"code":"ER_TRUNCATED_WRONG_VALUE_FOR_FIELD","errno":1366,"sqlState":"HY000","sqlMessage":"Incorrect integer value: '' for column 'start' at row 1","sql":"INSERT INTO `gannt` (`id`,`label`,`user`,`start`,`endDate`,`duration`,`percent`,`type`,`proType`,`risk`) VALUES (DEFAULT,?,?,?,?,?,?,?,?,?);","parameters":["asdf","","",null,1,10,"","",""]}
sql: "INSERT INTO `gannt` (`id`,`label`,`user`,`start`,`endDate`,`duration`,`percent`,`type`,`proType`,`risk`) VALUES (DEFAULT,?,?,?,?,?,?,?,?,?);"
parameters: ["asdf","","",null,1,10,"","",""]
headers: {"Access-Control-Allow-Origin":"*","vary":"Origin"}
pid: 92123
hostname: lxddeMacBook-Pro.local

2020-09-30 17:09:45,844 ERROR 92123 [-/192.168.7.50/-/5ms POST /gannt/created] nodejs.SequelizeDatabaseError: Incorrect integer value: '' for column 'start' at row 1
    at Query.formatError (/Users/lxd/Desktop/egg-example/node_modules/sequelize/lib/dialects/mysql/query.js:239:16)
    at Query.run (/Users/lxd/Desktop/egg-example/node_modules/sequelize/lib/dialects/mysql/query.js:54:18)
    at processTicksAndRejections (internal/process/task_queues.js:97:5)
name: "SequelizeDatabaseError"
parent: {"code":"ER_TRUNCATED_WRONG_VALUE_FOR_FIELD","errno":1366,"sqlState":"HY000","sqlMessage":"Incorrect integer value: '' for column 'start' at row 1","sql":"INSERT INTO `gannt` (`id`,`label`,`user`,`start`,`endDate`,`duration`,`percent`,`type`,`proType`,`risk`) VALUES (DEFAULT,?,?,?,?,?,?,?,?,?);","parameters":["asdf","","",null,1,10,"","",""]}
original: {"code":"ER_TRUNCATED_WRONG_VALUE_FOR_FIELD","errno":1366,"sqlState":"HY000","sqlMessage":"Incorrect integer value: '' for column 'start' at row 1","sql":"INSERT INTO `gannt` (`id`,`label`,`user`,`start`,`endDate`,`duration`,`percent`,`type`,`proType`,`risk`) VALUES (DEFAULT,?,?,?,?,?,?,?,?,?);","parameters":["asdf","","",null,1,10,"","",""]}
sql: "INSERT INTO `gannt` (`id`,`label`,`user`,`start`,`endDate`,`duration`,`percent`,`type`,`proType`,`risk`) VALUES (DEFAULT,?,?,?,?,?,?,?,?,?);"
parameters: ["asdf","","",null,1,10,"","",""]
headers: {"Access-Control-Allow-Origin":"*","vary":"Origin"}
pid: 92123
hostname: lxddeMacBook-Pro.local

2020-09-30 17:10:06,242 ERROR 92219 [-/192.168.7.50/-/17ms POST /gannt/created] nodejs.SequelizeDatabaseError: Incorrect integer value: '' for column 'start' at row 1
    at Query.formatError (/Users/lxd/Desktop/egg-example/node_modules/sequelize/lib/dialects/mysql/query.js:239:16)
    at Query.run (/Users/lxd/Desktop/egg-example/node_modules/sequelize/lib/dialects/mysql/query.js:54:18)
    at processTicksAndRejections (internal/process/task_queues.js:97:5)
name: "SequelizeDatabaseError"
parent: {"code":"ER_TRUNCATED_WRONG_VALUE_FOR_FIELD","errno":1366,"sqlState":"HY000","sqlMessage":"Incorrect integer value: '' for column 'start' at row 1","sql":"INSERT INTO `gannt` (`id`,`label`,`user`,`start`,`endDate`,`duration`,`percent`,`type`,`proType`,`risk`) VALUES (DEFAULT,?,?,?,?,?,?,?,?,?);","parameters":["111","","",null,1,10,"","",""]}
original: {"code":"ER_TRUNCATED_WRONG_VALUE_FOR_FIELD","errno":1366,"sqlState":"HY000","sqlMessage":"Incorrect integer value: '' for column 'start' at row 1","sql":"INSERT INTO `gannt` (`id`,`label`,`user`,`start`,`endDate`,`duration`,`percent`,`type`,`proType`,`risk`) VALUES (DEFAULT,?,?,?,?,?,?,?,?,?);","parameters":["111","","",null,1,10,"","",""]}
sql: "INSERT INTO `gannt` (`id`,`label`,`user`,`start`,`endDate`,`duration`,`percent`,`type`,`proType`,`risk`) VALUES (DEFAULT,?,?,?,?,?,?,?,?,?);"
parameters: ["111","","",null,1,10,"","",""]
headers: {"Access-Control-Allow-Origin":"*","vary":"Origin"}
pid: 92219
hostname: lxddeMacBook-Pro.local

2020-09-30 17:11:20,846 ERROR 92219 [-/192.168.7.50/-/8ms POST /gannt/created] nodejs.SequelizeDatabaseError: Out of range value for column 'start' at row 1
    at Query.formatError (/Users/lxd/Desktop/egg-example/node_modules/sequelize/lib/dialects/mysql/query.js:239:16)
    at Query.run (/Users/lxd/Desktop/egg-example/node_modules/sequelize/lib/dialects/mysql/query.js:54:18)
    at processTicksAndRejections (internal/process/task_queues.js:97:5)
name: "SequelizeDatabaseError"
parent: {"code":"ER_WARN_DATA_OUT_OF_RANGE","errno":1264,"sqlState":"22003","sqlMessage":"Out of range value for column 'start' at row 1","sql":"INSERT INTO `gannt` (`id`,`label`,`user`,`start`,`endDate`,`duration`,`percent`,`type`,`proType`,`risk`) VALUES (DEFAULT,?,?,?,?,?,?,?,?,?);","parameters":["1","1",1601136000000,1601222400000,1,10,"","1","1"]}
original: {"code":"ER_WARN_DATA_OUT_OF_RANGE","errno":1264,"sqlState":"22003","sqlMessage":"Out of range value for column 'start' at row 1","sql":"INSERT INTO `gannt` (`id`,`label`,`user`,`start`,`endDate`,`duration`,`percent`,`type`,`proType`,`risk`) VALUES (DEFAULT,?,?,?,?,?,?,?,?,?);","parameters":["1","1",1601136000000,1601222400000,1,10,"","1","1"]}
sql: "INSERT INTO `gannt` (`id`,`label`,`user`,`start`,`endDate`,`duration`,`percent`,`type`,`proType`,`risk`) VALUES (DEFAULT,?,?,?,?,?,?,?,?,?);"
parameters: ["1","1",1601136000000,1601222400000,1,10,"","1","1"]
headers: {"Access-Control-Allow-Origin":"*","vary":"Origin"}
pid: 92219
hostname: lxddeMacBook-Pro.local

2020-09-30 17:15:48,693 ERROR 92219 [-/192.168.7.50/-/3ms POST /gannt/created] nodejs.SequelizeDatabaseError: Incorrect integer value: '' for column 'start' at row 1
    at Query.formatError (/Users/lxd/Desktop/egg-example/node_modules/sequelize/lib/dialects/mysql/query.js:239:16)
    at Query.run (/Users/lxd/Desktop/egg-example/node_modules/sequelize/lib/dialects/mysql/query.js:54:18)
    at processTicksAndRejections (internal/process/task_queues.js:97:5)
name: "SequelizeDatabaseError"
parent: {"code":"ER_TRUNCATED_WRONG_VALUE_FOR_FIELD","errno":1366,"sqlState":"HY000","sqlMessage":"Incorrect integer value: '' for column 'start' at row 1","sql":"INSERT INTO `gannt` (`id`,`label`,`user`,`start`,`endDate`,`duration`,`percent`,`type`,`proType`,`risk`) VALUES (DEFAULT,?,?,?,?,?,?,?,?,?);","parameters":["asdf","asdf","",null,null,10,"","a","a"]}
original: {"code":"ER_TRUNCATED_WRONG_VALUE_FOR_FIELD","errno":1366,"sqlState":"HY000","sqlMessage":"Incorrect integer value: '' for column 'start' at row 1","sql":"INSERT INTO `gannt` (`id`,`label`,`user`,`start`,`endDate`,`duration`,`percent`,`type`,`proType`,`risk`) VALUES (DEFAULT,?,?,?,?,?,?,?,?,?);","parameters":["asdf","asdf","",null,null,10,"","a","a"]}
sql: "INSERT INTO `gannt` (`id`,`label`,`user`,`start`,`endDate`,`duration`,`percent`,`type`,`proType`,`risk`) VALUES (DEFAULT,?,?,?,?,?,?,?,?,?);"
parameters: ["asdf","asdf","",null,null,10,"","a","a"]
headers: {"Access-Control-Allow-Origin":"*","vary":"Origin"}
pid: 92219
hostname: lxddeMacBook-Pro.local

2020-09-30 17:30:17,280 ERROR 92219 [-/192.168.7.50/-/8ms POST /gannt/created] nodejs.SequelizeUniqueConstraintError: Validation error
    at Query.formatError (/Users/lxd/Desktop/egg-example/node_modules/sequelize/lib/dialects/mysql/query.js:218:16)
    at Query.run (/Users/lxd/Desktop/egg-example/node_modules/sequelize/lib/dialects/mysql/query.js:54:18)
    at processTicksAndRejections (internal/process/task_queues.js:97:5)
name: "SequelizeUniqueConstraintError"
errors: [{"message":"gannt.PRIMARY must be unique","type":"unique violation","path":"gannt.PRIMARY","value":"3","origin":"DB","instance":{"id":3,"label":"需求2","user":"John Doe","start":-120,"endDate":"2020-07-21","duration":1209600000,"percent":85,"type":"milestone","proType":"产品需求","risk":"风险预警xxx"},"validatorKey":"not_unique","validatorName":null,"validatorArgs":[]}]
fields: {"gannt.PRIMARY":"3"}
parent: {"code":"ER_DUP_ENTRY","errno":1062,"sqlState":"23000","sqlMessage":"Duplicate entry '3' for key 'gannt.PRIMARY'","sql":"INSERT INTO `gannt` (`id`,`label`,`user`,`start`,`endDate`,`duration`,`percent`,`type`,`proType`,`risk`) VALUES (?,?,?,?,?,?,?,?,?,?);","parameters":[3,"需求2","John Doe",-120,"2020-07-21",1209600000,85,"milestone","产品需求","风险预警xxx"]}
original: {"code":"ER_DUP_ENTRY","errno":1062,"sqlState":"23000","sqlMessage":"Duplicate entry '3' for key 'gannt.PRIMARY'","sql":"INSERT INTO `gannt` (`id`,`label`,`user`,`start`,`endDate`,`duration`,`percent`,`type`,`proType`,`risk`) VALUES (?,?,?,?,?,?,?,?,?,?);","parameters":[3,"需求2","John Doe",-120,"2020-07-21",1209600000,85,"milestone","产品需求","风险预警xxx"]}
sql: "INSERT INTO `gannt` (`id`,`label`,`user`,`start`,`endDate`,`duration`,`percent`,`type`,`proType`,`risk`) VALUES (?,?,?,?,?,?,?,?,?,?);"
headers: {"Access-Control-Allow-Origin":"*","vary":"Origin"}
pid: 92219
hostname: lxddeMacBook-Pro.local

2020-09-30 17:43:40,832 ERROR 92219 [-/192.168.7.50/-/5ms POST /gannt/created] nodejs.SequelizeDatabaseError: Incorrect datetime value: '-120' for column 'start' at row 1
    at Query.formatError (/Users/lxd/Desktop/egg-example/node_modules/sequelize/lib/dialects/mysql/query.js:239:16)
    at Query.run (/Users/lxd/Desktop/egg-example/node_modules/sequelize/lib/dialects/mysql/query.js:54:18)
    at processTicksAndRejections (internal/process/task_queues.js:97:5)
name: "SequelizeDatabaseError"
parent: {"code":"ER_TRUNCATED_WRONG_VALUE","errno":1292,"sqlState":"22007","sqlMessage":"Incorrect datetime value: '-120' for column 'start' at row 1","sql":"INSERT INTO `gannt` (`id`,`label`,`user`,`start`,`endDate`,`duration`,`percent`,`type`,`proType`,`risk`) VALUES (?,?,?,?,?,?,?,?,?,?);","parameters":[3,"需求2","John Doe",-120,"2020-07-21",1209600000,85,"milestone","产品需求","风险预警xxx"]}
original: {"code":"ER_TRUNCATED_WRONG_VALUE","errno":1292,"sqlState":"22007","sqlMessage":"Incorrect datetime value: '-120' for column 'start' at row 1","sql":"INSERT INTO `gannt` (`id`,`label`,`user`,`start`,`endDate`,`duration`,`percent`,`type`,`proType`,`risk`) VALUES (?,?,?,?,?,?,?,?,?,?);","parameters":[3,"需求2","John Doe",-120,"2020-07-21",1209600000,85,"milestone","产品需求","风险预警xxx"]}
sql: "INSERT INTO `gannt` (`id`,`label`,`user`,`start`,`endDate`,`duration`,`percent`,`type`,`proType`,`risk`) VALUES (?,?,?,?,?,?,?,?,?,?);"
parameters: [3,"需求2","John Doe",-120,"2020-07-21",1209600000,85,"milestone","产品需求","风险预警xxx"]
headers: {"Access-Control-Allow-Origin":"*","vary":"Origin"}
pid: 92219
hostname: lxddeMacBook-Pro.local

2020-09-30 17:44:52,617 ERROR 92219 [-/192.168.7.50/-/5ms POST /gannt/created] nodejs.SequelizeDatabaseError: Incorrect datetime value: '1209600000' for column 'start' at row 1
    at Query.formatError (/Users/lxd/Desktop/egg-example/node_modules/sequelize/lib/dialects/mysql/query.js:239:16)
    at Query.run (/Users/lxd/Desktop/egg-example/node_modules/sequelize/lib/dialects/mysql/query.js:54:18)
    at processTicksAndRejections (internal/process/task_queues.js:97:5)
name: "SequelizeDatabaseError"
parent: {"code":"ER_TRUNCATED_WRONG_VALUE","errno":1292,"sqlState":"22007","sqlMessage":"Incorrect datetime value: '1209600000' for column 'start' at row 1","sql":"INSERT INTO `gannt` (`id`,`label`,`user`,`start`,`endDate`,`duration`,`percent`,`type`,`proType`,`risk`) VALUES (?,?,?,?,?,?,?,?,?,?);","parameters":[3,"需求2","John Doe",1209600000,"2020-07-21",1209600000,85,"milestone","产品需求","风险预警xxx"]}
original: {"code":"ER_TRUNCATED_WRONG_VALUE","errno":1292,"sqlState":"22007","sqlMessage":"Incorrect datetime value: '1209600000' for column 'start' at row 1","sql":"INSERT INTO `gannt` (`id`,`label`,`user`,`start`,`endDate`,`duration`,`percent`,`type`,`proType`,`risk`) VALUES (?,?,?,?,?,?,?,?,?,?);","parameters":[3,"需求2","John Doe",1209600000,"2020-07-21",1209600000,85,"milestone","产品需求","风险预警xxx"]}
sql: "INSERT INTO `gannt` (`id`,`label`,`user`,`start`,`endDate`,`duration`,`percent`,`type`,`proType`,`risk`) VALUES (?,?,?,?,?,?,?,?,?,?);"
parameters: [3,"需求2","John Doe",1209600000,"2020-07-21",1209600000,85,"milestone","产品需求","风险预警xxx"]
headers: {"Access-Control-Allow-Origin":"*","vary":"Origin"}
pid: 92219
hostname: lxddeMacBook-Pro.local

2020-09-30 17:45:25,425 ERROR 92219 [-/192.168.7.50/-/5ms POST /gannt/created] nodejs.SequelizeDatabaseError: Incorrect datetime value: '1601222400000' for column 'start' at row 1
    at Query.formatError (/Users/lxd/Desktop/egg-example/node_modules/sequelize/lib/dialects/mysql/query.js:239:16)
    at Query.run (/Users/lxd/Desktop/egg-example/node_modules/sequelize/lib/dialects/mysql/query.js:54:18)
    at processTicksAndRejections (internal/process/task_queues.js:97:5)
name: "SequelizeDatabaseError"
parent: {"code":"ER_TRUNCATED_WRONG_VALUE","errno":1292,"sqlState":"22007","sqlMessage":"Incorrect datetime value: '1601222400000' for column 'start' at row 1","sql":"INSERT INTO `gannt` (`id`,`label`,`user`,`start`,`endDate`,`duration`,`percent`,`type`,`proType`,`risk`) VALUES (?,?,?,?,?,?,?,?,?,?);","parameters":[3,"需求2","John Doe",1601222400000,"2020-07-21",1209600000,85,"milestone","产品需求","风险预警xxx"]}
original: {"code":"ER_TRUNCATED_WRONG_VALUE","errno":1292,"sqlState":"22007","sqlMessage":"Incorrect datetime value: '1601222400000' for column 'start' at row 1","sql":"INSERT INTO `gannt` (`id`,`label`,`user`,`start`,`endDate`,`duration`,`percent`,`type`,`proType`,`risk`) VALUES (?,?,?,?,?,?,?,?,?,?);","parameters":[3,"需求2","John Doe",1601222400000,"2020-07-21",1209600000,85,"milestone","产品需求","风险预警xxx"]}
sql: "INSERT INTO `gannt` (`id`,`label`,`user`,`start`,`endDate`,`duration`,`percent`,`type`,`proType`,`risk`) VALUES (?,?,?,?,?,?,?,?,?,?);"
parameters: [3,"需求2","John Doe",1601222400000,"2020-07-21",1209600000,85,"milestone","产品需求","风险预警xxx"]
headers: {"Access-Control-Allow-Origin":"*","vary":"Origin"}
pid: 92219
hostname: lxddeMacBook-Pro.local

2020-09-30 17:45:45,943 ERROR 92219 [-/192.168.7.50/-/2ms POST /gannt/created] nodejs.SequelizeDatabaseError: Incorrect datetime value: '1601222400000' for column 'start' at row 1
    at Query.formatError (/Users/lxd/Desktop/egg-example/node_modules/sequelize/lib/dialects/mysql/query.js:239:16)
    at Query.run (/Users/lxd/Desktop/egg-example/node_modules/sequelize/lib/dialects/mysql/query.js:54:18)
    at processTicksAndRejections (internal/process/task_queues.js:97:5)
name: "SequelizeDatabaseError"
parent: {"code":"ER_TRUNCATED_WRONG_VALUE","errno":1292,"sqlState":"22007","sqlMessage":"Incorrect datetime value: '1601222400000' for column 'start' at row 1","sql":"INSERT INTO `gannt` (`id`,`label`,`user`,`start`,`endDate`,`duration`,`percent`,`type`,`proType`,`risk`) VALUES (?,?,?,?,?,?,?,?,?,?);","parameters":[3,"需求2","John Doe",1601222400000,"2020-07-21",1209600000,85,"milestone","产品需求","风险预警xxx"]}
original: {"code":"ER_TRUNCATED_WRONG_VALUE","errno":1292,"sqlState":"22007","sqlMessage":"Incorrect datetime value: '1601222400000' for column 'start' at row 1","sql":"INSERT INTO `gannt` (`id`,`label`,`user`,`start`,`endDate`,`duration`,`percent`,`type`,`proType`,`risk`) VALUES (?,?,?,?,?,?,?,?,?,?);","parameters":[3,"需求2","John Doe",1601222400000,"2020-07-21",1209600000,85,"milestone","产品需求","风险预警xxx"]}
sql: "INSERT INTO `gannt` (`id`,`label`,`user`,`start`,`endDate`,`duration`,`percent`,`type`,`proType`,`risk`) VALUES (?,?,?,?,?,?,?,?,?,?);"
parameters: [3,"需求2","John Doe",1601222400000,"2020-07-21",1209600000,85,"milestone","产品需求","风险预警xxx"]
headers: {"Access-Control-Allow-Origin":"*","vary":"Origin"}
pid: 92219
hostname: lxddeMacBook-Pro.local

2020-09-30 17:46:38,743 ERROR 92219 [-/192.168.7.50/-/3ms POST /gannt/created] nodejs.SequelizeDatabaseError: Incorrect datetime value: '1601222400000' for column 'start' at row 1
    at Query.formatError (/Users/lxd/Desktop/egg-example/node_modules/sequelize/lib/dialects/mysql/query.js:239:16)
    at Query.run (/Users/lxd/Desktop/egg-example/node_modules/sequelize/lib/dialects/mysql/query.js:54:18)
    at processTicksAndRejections (internal/process/task_queues.js:97:5)
name: "SequelizeDatabaseError"
parent: {"code":"ER_TRUNCATED_WRONG_VALUE","errno":1292,"sqlState":"22007","sqlMessage":"Incorrect datetime value: '1601222400000' for column 'start' at row 1","sql":"INSERT INTO `gannt` (`id`,`label`,`user`,`start`,`endDate`,`duration`,`percent`,`type`,`proType`,`risk`) VALUES (?,?,?,?,?,?,?,?,?,?);","parameters":[3,"需求2","John Doe","1601222400000","2020-07-21",1209600000,85,"milestone","产品需求","风险预警xxx"]}
original: {"code":"ER_TRUNCATED_WRONG_VALUE","errno":1292,"sqlState":"22007","sqlMessage":"Incorrect datetime value: '1601222400000' for column 'start' at row 1","sql":"INSERT INTO `gannt` (`id`,`label`,`user`,`start`,`endDate`,`duration`,`percent`,`type`,`proType`,`risk`) VALUES (?,?,?,?,?,?,?,?,?,?);","parameters":[3,"需求2","John Doe","1601222400000","2020-07-21",1209600000,85,"milestone","产品需求","风险预警xxx"]}
sql: "INSERT INTO `gannt` (`id`,`label`,`user`,`start`,`endDate`,`duration`,`percent`,`type`,`proType`,`risk`) VALUES (?,?,?,?,?,?,?,?,?,?);"
parameters: [3,"需求2","John Doe","1601222400000","2020-07-21",1209600000,85,"milestone","产品需求","风险预警xxx"]
headers: {"Access-Control-Allow-Origin":"*","vary":"Origin"}
pid: 92219
hostname: lxddeMacBook-Pro.local

2020-09-30 17:48:04,994 ERROR 92219 [-/192.168.7.50/-/2ms POST /gannt/created] nodejs.SequelizeDatabaseError: Incorrect datetime value: '1601222400' for column 'start' at row 1
    at Query.formatError (/Users/lxd/Desktop/egg-example/node_modules/sequelize/lib/dialects/mysql/query.js:239:16)
    at Query.run (/Users/lxd/Desktop/egg-example/node_modules/sequelize/lib/dialects/mysql/query.js:54:18)
    at processTicksAndRejections (internal/process/task_queues.js:97:5)
name: "SequelizeDatabaseError"
parent: {"code":"ER_TRUNCATED_WRONG_VALUE","errno":1292,"sqlState":"22007","sqlMessage":"Incorrect datetime value: '1601222400' for column 'start' at row 1","sql":"INSERT INTO `gannt` (`id`,`label`,`user`,`start`,`endDate`,`duration`,`percent`,`type`,`proType`,`risk`) VALUES (?,?,?,?,?,?,?,?,?,?);","parameters":[3,"需求2","John Doe",1601222400,"2020-07-21",1209600000,85,"milestone","产品需求","风险预警xxx"]}
original: {"code":"ER_TRUNCATED_WRONG_VALUE","errno":1292,"sqlState":"22007","sqlMessage":"Incorrect datetime value: '1601222400' for column 'start' at row 1","sql":"INSERT INTO `gannt` (`id`,`label`,`user`,`start`,`endDate`,`duration`,`percent`,`type`,`proType`,`risk`) VALUES (?,?,?,?,?,?,?,?,?,?);","parameters":[3,"需求2","John Doe",1601222400,"2020-07-21",1209600000,85,"milestone","产品需求","风险预警xxx"]}
sql: "INSERT INTO `gannt` (`id`,`label`,`user`,`start`,`endDate`,`duration`,`percent`,`type`,`proType`,`risk`) VALUES (?,?,?,?,?,?,?,?,?,?);"
parameters: [3,"需求2","John Doe",1601222400,"2020-07-21",1209600000,85,"milestone","产品需求","风险预警xxx"]
headers: {"Access-Control-Allow-Origin":"*","vary":"Origin"}
pid: 92219
hostname: lxddeMacBook-Pro.local

2020-09-30 18:05:33,981 ERROR 92219 [-/192.168.7.50/-/2ms POST /gannt/created] nodejs.SequelizeDatabaseError: Incorrect datetime value: '1599494400000' for column 'start' at row 1
    at Query.formatError (/Users/lxd/Desktop/egg-example/node_modules/sequelize/lib/dialects/mysql/query.js:239:16)
    at Query.run (/Users/lxd/Desktop/egg-example/node_modules/sequelize/lib/dialects/mysql/query.js:54:18)
    at processTicksAndRejections (internal/process/task_queues.js:97:5)
name: "SequelizeDatabaseError"
parent: {"code":"ER_TRUNCATED_WRONG_VALUE","errno":1292,"sqlState":"22007","sqlMessage":"Incorrect datetime value: '1599494400000' for column 'start' at row 1","sql":"INSERT INTO `gannt` (`id`,`label`,`user`,`start`,`endDate`,`duration`,`percent`,`type`,`proType`,`risk`) VALUES (?,?,?,?,?,?,?,?,?,?);","parameters":[3,"需求2","John Doe",1599494400000,"2020-07-21",1209600000,85,"milestone","产品需求","风险预警xxx"]}
original: {"code":"ER_TRUNCATED_WRONG_VALUE","errno":1292,"sqlState":"22007","sqlMessage":"Incorrect datetime value: '1599494400000' for column 'start' at row 1","sql":"INSERT INTO `gannt` (`id`,`label`,`user`,`start`,`endDate`,`duration`,`percent`,`type`,`proType`,`risk`) VALUES (?,?,?,?,?,?,?,?,?,?);","parameters":[3,"需求2","John Doe",1599494400000,"2020-07-21",1209600000,85,"milestone","产品需求","风险预警xxx"]}
sql: "INSERT INTO `gannt` (`id`,`label`,`user`,`start`,`endDate`,`duration`,`percent`,`type`,`proType`,`risk`) VALUES (?,?,?,?,?,?,?,?,?,?);"
parameters: [3,"需求2","John Doe",1599494400000,"2020-07-21",1209600000,85,"milestone","产品需求","风险预警xxx"]
headers: {"Access-Control-Allow-Origin":"*","vary":"Origin"}
pid: 92219
hostname: lxddeMacBook-Pro.local

2020-09-30 18:13:46,687 ERROR 94111 [-/192.168.7.50/-/26ms POST /gannt/created] nodejs.SequelizeDatabaseError: Incorrect datetime value: '' for column 'start' at row 1
    at Query.formatError (/Users/lxd/Desktop/egg-example/node_modules/sequelize/lib/dialects/mysql/query.js:239:16)
    at Query.run (/Users/lxd/Desktop/egg-example/node_modules/sequelize/lib/dialects/mysql/query.js:54:18)
    at processTicksAndRejections (internal/process/task_queues.js:97:5)
name: "SequelizeDatabaseError"
parent: {"code":"ER_TRUNCATED_WRONG_VALUE","errno":1292,"sqlState":"22007","sqlMessage":"Incorrect datetime value: '' for column 'start' at row 1","sql":"INSERT INTO `gannt` (`id`,`label`,`user`,`start`,`endDate`,`duration`,`percent`,`type`,`proType`,`risk`) VALUES (?,?,?,?,?,?,?,?,?,?);","parameters":[3,"需求2","John Doe","","2020-07-21",1209600000,85,"milestone","产品需求","风险预警xxx"]}
original: {"code":"ER_TRUNCATED_WRONG_VALUE","errno":1292,"sqlState":"22007","sqlMessage":"Incorrect datetime value: '' for column 'start' at row 1","sql":"INSERT INTO `gannt` (`id`,`label`,`user`,`start`,`endDate`,`duration`,`percent`,`type`,`proType`,`risk`) VALUES (?,?,?,?,?,?,?,?,?,?);","parameters":[3,"需求2","John Doe","","2020-07-21",1209600000,85,"milestone","产品需求","风险预警xxx"]}
sql: "INSERT INTO `gannt` (`id`,`label`,`user`,`start`,`endDate`,`duration`,`percent`,`type`,`proType`,`risk`) VALUES (?,?,?,?,?,?,?,?,?,?);"
parameters: [3,"需求2","John Doe","","2020-07-21",1209600000,85,"milestone","产品需求","风险预警xxx"]
headers: {"Access-Control-Allow-Origin":"*","vary":"Origin"}
pid: 94111
hostname: lxddeMacBook-Pro.local

2020-09-30 18:14:00,281 ERROR 94111 [-/192.168.7.50/-/10ms POST /gannt/created] nodejs.SequelizeUniqueConstraintError: Validation error
    at Query.formatError (/Users/lxd/Desktop/egg-example/node_modules/sequelize/lib/dialects/mysql/query.js:218:16)
    at Query.run (/Users/lxd/Desktop/egg-example/node_modules/sequelize/lib/dialects/mysql/query.js:54:18)
    at processTicksAndRejections (internal/process/task_queues.js:97:5)
name: "SequelizeUniqueConstraintError"
errors: [{"message":"gannt.PRIMARY must be unique","type":"unique violation","path":"gannt.PRIMARY","value":"3","origin":"DB","instance":{"id":3,"label":"需求2","user":"John Doe","start":"2020-09-20 00-00-00","endDate":"2020-07-21","duration":1209600000,"percent":85,"type":"milestone","proType":"产品需求","risk":"风险预警xxx"},"validatorKey":"not_unique","validatorName":null,"validatorArgs":[]}]
fields: {"gannt.PRIMARY":"3"}
parent: {"code":"ER_DUP_ENTRY","errno":1062,"sqlState":"23000","sqlMessage":"Duplicate entry '3' for key 'gannt.PRIMARY'","sql":"INSERT INTO `gannt` (`id`,`label`,`user`,`start`,`endDate`,`duration`,`percent`,`type`,`proType`,`risk`) VALUES (?,?,?,?,?,?,?,?,?,?);","parameters":[3,"需求2","John Doe","2020-09-20 00-00-00","2020-07-21",1209600000,85,"milestone","产品需求","风险预警xxx"]}
original: {"code":"ER_DUP_ENTRY","errno":1062,"sqlState":"23000","sqlMessage":"Duplicate entry '3' for key 'gannt.PRIMARY'","sql":"INSERT INTO `gannt` (`id`,`label`,`user`,`start`,`endDate`,`duration`,`percent`,`type`,`proType`,`risk`) VALUES (?,?,?,?,?,?,?,?,?,?);","parameters":[3,"需求2","John Doe","2020-09-20 00-00-00","2020-07-21",1209600000,85,"milestone","产品需求","风险预警xxx"]}
sql: "INSERT INTO `gannt` (`id`,`label`,`user`,`start`,`endDate`,`duration`,`percent`,`type`,`proType`,`risk`) VALUES (?,?,?,?,?,?,?,?,?,?);"
headers: {"Access-Control-Allow-Origin":"*","vary":"Origin"}
pid: 94111
hostname: lxddeMacBook-Pro.local

2020-09-30 18:32:28,848 ERROR 94111 [-/192.168.7.50/-/4ms POST /gannt/created] nodejs.SequelizeDatabaseError: Incorrect datetime value: '1600099200000' for column 'endDate' at row 1
    at Query.formatError (/Users/lxd/Desktop/egg-example/node_modules/sequelize/lib/dialects/mysql/query.js:239:16)
    at Query.run (/Users/lxd/Desktop/egg-example/node_modules/sequelize/lib/dialects/mysql/query.js:54:18)
    at processTicksAndRejections (internal/process/task_queues.js:97:5)
name: "SequelizeDatabaseError"
parent: {"code":"ER_TRUNCATED_WRONG_VALUE","errno":1292,"sqlState":"22007","sqlMessage":"Incorrect datetime value: '1600099200000' for column 'endDate' at row 1","sql":"INSERT INTO `gannt` (`id`,`label`,`user`,`start`,`endDate`,`duration`,`percent`,`type`,`proType`,`risk`) VALUES (?,?,?,?,?,?,?,?,?,?);","parameters":["1","直播","allan","2020-09-01 00-00-00",1600099200000,null,10,"","紧急","无"]}
original: {"code":"ER_TRUNCATED_WRONG_VALUE","errno":1292,"sqlState":"22007","sqlMessage":"Incorrect datetime value: '1600099200000' for column 'endDate' at row 1","sql":"INSERT INTO `gannt` (`id`,`label`,`user`,`start`,`endDate`,`duration`,`percent`,`type`,`proType`,`risk`) VALUES (?,?,?,?,?,?,?,?,?,?);","parameters":["1","直播","allan","2020-09-01 00-00-00",1600099200000,null,10,"","紧急","无"]}
sql: "INSERT INTO `gannt` (`id`,`label`,`user`,`start`,`endDate`,`duration`,`percent`,`type`,`proType`,`risk`) VALUES (?,?,?,?,?,?,?,?,?,?);"
parameters: ["1","直播","allan","2020-09-01 00-00-00",1600099200000,null,10,"","紧急","无"]
headers: {"Access-Control-Allow-Origin":"*","vary":"Origin"}
pid: 94111
hostname: lxddeMacBook-Pro.local

2020-09-30 20:16:51,002 ERROR 60251 nodejs.ClusterClientNoResponseError: client no response in 4527570ms exceeding maxIdleTime 60000ms, maybe the connection is close on other side.
    at Timeout._onTimeout (/Users/lxd/Desktop/egg-example/node_modules/cluster-client/lib/leader.js:77:23)
    at listOnTimeout (internal/timers.js:549:17)
    at processTimers (internal/timers.js:492:7)
name: "ClusterClientNoResponseError"
pid: 60251
hostname: lxddeMacBook-Pro.local

2020-10-01 08:42:57,837 ERROR 60251 nodejs.ClusterClientNoResponseError: client no response in 44706812ms exceeding maxIdleTime 60000ms, maybe the connection is close on other side.
    at Timeout._onTimeout (/Users/lxd/Desktop/egg-example/node_modules/cluster-client/lib/leader.js:77:23)
    at listOnTimeout (internal/timers.js:549:17)
    at processTimers (internal/timers.js:492:7)
name: "ClusterClientNoResponseError"
pid: 60251
hostname: lxddeMacBook-Pro.local

2020-10-01 10:04:42,967 ERROR 96469 nodejs.ClusterClientNoResponseError: client no response in 574005ms exceeding maxIdleTime 60000ms, maybe the connection is close on other side.
    at Timeout._onTimeout (/Users/lxd/Desktop/egg-example/node_modules/cluster-client/lib/leader.js:77:23)
    at listOnTimeout (internal/timers.js:549:17)
    at processTimers (internal/timers.js:492:7)
name: "ClusterClientNoResponseError"
pid: 96469
hostname: localhost

2020-10-01 10:14:57,921 ERROR 96469 nodejs.ClusterClientNoResponseError: client no response in 574935ms exceeding maxIdleTime 60000ms, maybe the connection is close on other side.
    at Timeout._onTimeout (/Users/lxd/Desktop/egg-example/node_modules/cluster-client/lib/leader.js:77:23)
    at listOnTimeout (internal/timers.js:549:17)
    at processTimers (internal/timers.js:492:7)
name: "ClusterClientNoResponseError"
pid: 96469
hostname: localhost

2020-10-01 10:24:52,962 ERROR 96469 nodejs.ClusterClientNoResponseError: client no response in 575030ms exceeding maxIdleTime 60000ms, maybe the connection is close on other side.
    at Timeout._onTimeout (/Users/lxd/Desktop/egg-example/node_modules/cluster-client/lib/leader.js:77:23)
    at listOnTimeout (internal/timers.js:549:17)
    at processTimers (internal/timers.js:492:7)
name: "ClusterClientNoResponseError"
pid: 96469
hostname: localhost

2020-10-01 10:45:24,015 ERROR 96469 nodejs.ClusterClientNoResponseError: client no response in 575015ms exceeding maxIdleTime 60000ms, maybe the connection is close on other side.
    at Timeout._onTimeout (/Users/lxd/Desktop/egg-example/node_modules/cluster-client/lib/leader.js:77:23)
    at listOnTimeout (internal/timers.js:549:17)
    at processTimers (internal/timers.js:492:7)
name: "ClusterClientNoResponseError"
pid: 96469
hostname: localhost

2020-10-01 10:55:19,026 ERROR 96469 nodejs.ClusterClientNoResponseError: client no response in 574995ms exceeding maxIdleTime 60000ms, maybe the connection is close on other side.
    at Timeout._onTimeout (/Users/lxd/Desktop/egg-example/node_modules/cluster-client/lib/leader.js:77:23)
    at listOnTimeout (internal/timers.js:549:17)
    at processTimers (internal/timers.js:492:7)
name: "ClusterClientNoResponseError"
pid: 96469
hostname: localhost

2020-10-01 11:05:34,066 ERROR 96469 nodejs.ClusterClientNoResponseError: client no response in 575026ms exceeding maxIdleTime 60000ms, maybe the connection is close on other side.
    at Timeout._onTimeout (/Users/lxd/Desktop/egg-example/node_modules/cluster-client/lib/leader.js:77:23)
    at listOnTimeout (internal/timers.js:549:17)
    at processTimers (internal/timers.js:492:7)
name: "ClusterClientNoResponseError"
pid: 96469
hostname: localhost

2020-10-01 11:15:31,002 ERROR 96469 nodejs.ClusterClientNoResponseError: client no response in 576927ms exceeding maxIdleTime 60000ms, maybe the connection is close on other side.
    at Timeout._onTimeout (/Users/lxd/Desktop/egg-example/node_modules/cluster-client/lib/leader.js:77:23)
    at listOnTimeout (internal/timers.js:549:17)
    at processTimers (internal/timers.js:492:7)
name: "ClusterClientNoResponseError"
pid: 96469
hostname: localhost

2020-10-01 11:25:46,058 ERROR 96469 nodejs.ClusterClientNoResponseError: client no response in 575039ms exceeding maxIdleTime 60000ms, maybe the connection is close on other side.
    at Timeout._onTimeout (/Users/lxd/Desktop/egg-example/node_modules/cluster-client/lib/leader.js:77:23)
    at listOnTimeout (internal/timers.js:549:17)
    at processTimers (internal/timers.js:492:7)
name: "ClusterClientNoResponseError"
pid: 96469
hostname: localhost

2020-10-02 22:43:48,491 ERROR 16165 nodejs.ClusterClientNoResponseError: client no response in 573906ms exceeding maxIdleTime 60000ms, maybe the connection is close on other side.
    at Timeout._onTimeout (/Users/lxd/Desktop/mine/egg-example/node_modules/cluster-client/lib/leader.js:77:23)
    at listOnTimeout (internal/timers.js:549:17)
    at processTimers (internal/timers.js:492:7)
name: "ClusterClientNoResponseError"
pid: 16165
hostname: localhost

2020-10-02 22:54:03,606 ERROR 16165 nodejs.ClusterClientNoResponseError: client no response in 575101ms exceeding maxIdleTime 60000ms, maybe the connection is close on other side.
    at Timeout._onTimeout (/Users/lxd/Desktop/mine/egg-example/node_modules/cluster-client/lib/leader.js:77:23)
    at listOnTimeout (internal/timers.js:549:17)
    at processTimers (internal/timers.js:492:7)
name: "ClusterClientNoResponseError"
pid: 16165
hostname: localhost

2020-10-02 23:04:19,733 ERROR 16165 nodejs.ClusterClientNoResponseError: client no response in 576109ms exceeding maxIdleTime 60000ms, maybe the connection is close on other side.
    at Timeout._onTimeout (/Users/lxd/Desktop/mine/egg-example/node_modules/cluster-client/lib/leader.js:77:23)
    at listOnTimeout (internal/timers.js:549:17)
    at processTimers (internal/timers.js:492:7)
name: "ClusterClientNoResponseError"
pid: 16165
hostname: localhost

2020-10-02 23:14:14,825 ERROR 16165 nodejs.ClusterClientNoResponseError: client no response in 575086ms exceeding maxIdleTime 60000ms, maybe the connection is close on other side.
    at Timeout._onTimeout (/Users/lxd/Desktop/mine/egg-example/node_modules/cluster-client/lib/leader.js:77:23)
    at listOnTimeout (internal/timers.js:549:17)
    at processTimers (internal/timers.js:492:7)
name: "ClusterClientNoResponseError"
pid: 16165
hostname: localhost

2020-10-02 23:24:29,965 ERROR 16165 nodejs.ClusterClientNoResponseError: client no response in 575121ms exceeding maxIdleTime 60000ms, maybe the connection is close on other side.
    at Timeout._onTimeout (/Users/lxd/Desktop/mine/egg-example/node_modules/cluster-client/lib/leader.js:77:23)
    at listOnTimeout (internal/timers.js:549:17)
    at processTimers (internal/timers.js:492:7)
name: "ClusterClientNoResponseError"
pid: 16165
hostname: localhost

2020-10-02 23:34:45,057 ERROR 16165 nodejs.ClusterClientNoResponseError: client no response in 575075ms exceeding maxIdleTime 60000ms, maybe the connection is close on other side.
    at Timeout._onTimeout (/Users/lxd/Desktop/mine/egg-example/node_modules/cluster-client/lib/leader.js:77:23)
    at listOnTimeout (internal/timers.js:549:17)
    at processTimers (internal/timers.js:492:7)
name: "ClusterClientNoResponseError"
pid: 16165
hostname: localhost

2020-10-02 23:44:40,139 ERROR 16165 nodejs.ClusterClientNoResponseError: client no response in 575075ms exceeding maxIdleTime 60000ms, maybe the connection is close on other side.
    at Timeout._onTimeout (/Users/lxd/Desktop/mine/egg-example/node_modules/cluster-client/lib/leader.js:77:23)
    at listOnTimeout (internal/timers.js:549:17)
    at processTimers (internal/timers.js:492:7)
name: "ClusterClientNoResponseError"
pid: 16165
hostname: localhost

2020-10-02 23:54:56,224 ERROR 16165 nodejs.ClusterClientNoResponseError: client no response in 576072ms exceeding maxIdleTime 60000ms, maybe the connection is close on other side.
    at Timeout._onTimeout (/Users/lxd/Desktop/mine/egg-example/node_modules/cluster-client/lib/leader.js:77:23)
    at listOnTimeout (internal/timers.js:549:17)
    at processTimers (internal/timers.js:492:7)
name: "ClusterClientNoResponseError"
pid: 16165
hostname: localhost

2020-10-03 00:05:11,312 ERROR 16165 nodejs.ClusterClientNoResponseError: client no response in 575063ms exceeding maxIdleTime 60000ms, maybe the connection is close on other side.
    at Timeout._onTimeout (/Users/lxd/Desktop/mine/egg-example/node_modules/cluster-client/lib/leader.js:77:23)
    at listOnTimeout (internal/timers.js:549:17)
    at processTimers (internal/timers.js:492:7)
name: "ClusterClientNoResponseError"
pid: 16165
hostname: localhost

2020-10-03 00:15:06,388 ERROR 16165 nodejs.ClusterClientNoResponseError: client no response in 575061ms exceeding maxIdleTime 60000ms, maybe the connection is close on other side.
    at Timeout._onTimeout (/Users/lxd/Desktop/mine/egg-example/node_modules/cluster-client/lib/leader.js:77:23)
    at listOnTimeout (internal/timers.js:549:17)
    at processTimers (internal/timers.js:492:7)
name: "ClusterClientNoResponseError"
pid: 16165
hostname: localhost

2020-10-03 00:25:21,479 ERROR 16165 nodejs.ClusterClientNoResponseError: client no response in 575082ms exceeding maxIdleTime 60000ms, maybe the connection is close on other side.
    at Timeout._onTimeout (/Users/lxd/Desktop/mine/egg-example/node_modules/cluster-client/lib/leader.js:77:23)
    at listOnTimeout (internal/timers.js:549:17)
    at processTimers (internal/timers.js:492:7)
name: "ClusterClientNoResponseError"
pid: 16165
hostname: localhost

2020-10-03 00:35:17,001 ERROR 16165 nodejs.ClusterClientNoResponseError: client no response in 575514ms exceeding maxIdleTime 60000ms, maybe the connection is close on other side.
    at Timeout._onTimeout (/Users/lxd/Desktop/mine/egg-example/node_modules/cluster-client/lib/leader.js:77:23)
    at listOnTimeout (internal/timers.js:549:17)
    at processTimers (internal/timers.js:492:7)
name: "ClusterClientNoResponseError"
pid: 16165
hostname: localhost

2020-10-03 00:45:32,097 ERROR 16165 nodejs.ClusterClientNoResponseError: client no response in 575077ms exceeding maxIdleTime 60000ms, maybe the connection is close on other side.
    at Timeout._onTimeout (/Users/lxd/Desktop/mine/egg-example/node_modules/cluster-client/lib/leader.js:77:23)
    at listOnTimeout (internal/timers.js:549:17)
    at processTimers (internal/timers.js:492:7)
name: "ClusterClientNoResponseError"
pid: 16165
hostname: localhost

2020-10-03 00:55:48,198 ERROR 16165 nodejs.ClusterClientNoResponseError: client no response in 576087ms exceeding maxIdleTime 60000ms, maybe the connection is close on other side.
    at Timeout._onTimeout (/Users/lxd/Desktop/mine/egg-example/node_modules/cluster-client/lib/leader.js:77:23)
    at listOnTimeout (internal/timers.js:549:17)
    at processTimers (internal/timers.js:492:7)
name: "ClusterClientNoResponseError"
pid: 16165
hostname: localhost

2020-10-03 01:05:43,302 ERROR 16165 nodejs.ClusterClientNoResponseError: client no response in 575094ms exceeding maxIdleTime 60000ms, maybe the connection is close on other side.
    at Timeout._onTimeout (/Users/lxd/Desktop/mine/egg-example/node_modules/cluster-client/lib/leader.js:77:23)
    at listOnTimeout (internal/timers.js:549:17)
    at processTimers (internal/timers.js:492:7)
name: "ClusterClientNoResponseError"
pid: 16165
hostname: localhost

2020-10-03 01:26:13,467 ERROR 16165 nodejs.ClusterClientNoResponseError: client no response in 575077ms exceeding maxIdleTime 60000ms, maybe the connection is close on other side.
    at Timeout._onTimeout (/Users/lxd/Desktop/mine/egg-example/node_modules/cluster-client/lib/leader.js:77:23)
    at listOnTimeout (internal/timers.js:549:17)
    at processTimers (internal/timers.js:492:7)
name: "ClusterClientNoResponseError"
pid: 16165
hostname: localhost

2020-10-03 01:36:09,550 ERROR 16165 nodejs.ClusterClientNoResponseError: client no response in 576074ms exceeding maxIdleTime 60000ms, maybe the connection is close on other side.
    at Timeout._onTimeout (/Users/lxd/Desktop/mine/egg-example/node_modules/cluster-client/lib/leader.js:77:23)
    at listOnTimeout (internal/timers.js:549:17)
    at processTimers (internal/timers.js:492:7)
name: "ClusterClientNoResponseError"
pid: 16165
hostname: localhost

2020-10-03 01:46:24,654 ERROR 16165 nodejs.ClusterClientNoResponseError: client no response in 575081ms exceeding maxIdleTime 60000ms, maybe the connection is close on other side.
    at Timeout._onTimeout (/Users/lxd/Desktop/mine/egg-example/node_modules/cluster-client/lib/leader.js:77:23)
    at listOnTimeout (internal/timers.js:549:17)
    at processTimers (internal/timers.js:492:7)
name: "ClusterClientNoResponseError"
pid: 16165
hostname: localhost

2020-10-03 01:56:39,740 ERROR 16165 nodejs.ClusterClientNoResponseError: client no response in 575079ms exceeding maxIdleTime 60000ms, maybe the connection is close on other side.
    at Timeout._onTimeout (/Users/lxd/Desktop/mine/egg-example/node_modules/cluster-client/lib/leader.js:77:23)
    at listOnTimeout (internal/timers.js:549:17)
    at processTimers (internal/timers.js:492:7)
name: "ClusterClientNoResponseError"
pid: 16165
hostname: localhost

2020-10-03 02:06:34,837 ERROR 16165 nodejs.ClusterClientNoResponseError: client no response in 575088ms exceeding maxIdleTime 60000ms, maybe the connection is close on other side.
    at Timeout._onTimeout (/Users/lxd/Desktop/mine/egg-example/node_modules/cluster-client/lib/leader.js:77:23)
    at listOnTimeout (internal/timers.js:549:17)
    at processTimers (internal/timers.js:492:7)
name: "ClusterClientNoResponseError"
pid: 16165
hostname: localhost

2020-10-03 02:16:50,914 ERROR 16165 nodejs.ClusterClientNoResponseError: client no response in 576063ms exceeding maxIdleTime 60000ms, maybe the connection is close on other side.
    at Timeout._onTimeout (/Users/lxd/Desktop/mine/egg-example/node_modules/cluster-client/lib/leader.js:77:23)
    at listOnTimeout (internal/timers.js:549:17)
    at processTimers (internal/timers.js:492:7)
name: "ClusterClientNoResponseError"
pid: 16165
hostname: localhost

2020-10-03 02:27:06,004 ERROR 16165 nodejs.ClusterClientNoResponseError: client no response in 575078ms exceeding maxIdleTime 60000ms, maybe the connection is close on other side.
    at Timeout._onTimeout (/Users/lxd/Desktop/mine/egg-example/node_modules/cluster-client/lib/leader.js:77:23)
    at listOnTimeout (internal/timers.js:549:17)
    at processTimers (internal/timers.js:492:7)
name: "ClusterClientNoResponseError"
pid: 16165
hostname: localhost

2020-10-03 02:37:01,094 ERROR 16165 nodejs.ClusterClientNoResponseError: client no response in 575074ms exceeding maxIdleTime 60000ms, maybe the connection is close on other side.
    at Timeout._onTimeout (/Users/lxd/Desktop/mine/egg-example/node_modules/cluster-client/lib/leader.js:77:23)
    at listOnTimeout (internal/timers.js:549:17)
    at processTimers (internal/timers.js:492:7)
name: "ClusterClientNoResponseError"
pid: 16165
hostname: localhost

2020-10-03 02:47:17,171 ERROR 16165 nodejs.ClusterClientNoResponseError: client no response in 576057ms exceeding maxIdleTime 60000ms, maybe the connection is close on other side.
    at Timeout._onTimeout (/Users/lxd/Desktop/mine/egg-example/node_modules/cluster-client/lib/leader.js:77:23)
    at listOnTimeout (internal/timers.js:549:17)
    at processTimers (internal/timers.js:492:7)
name: "ClusterClientNoResponseError"
pid: 16165
hostname: localhost

2020-10-03 02:57:13,002 ERROR 16165 nodejs.ClusterClientNoResponseError: client no response in 575821ms exceeding maxIdleTime 60000ms, maybe the connection is close on other side.
    at Timeout._onTimeout (/Users/lxd/Desktop/mine/egg-example/node_modules/cluster-client/lib/leader.js:77:23)
    at listOnTimeout (internal/timers.js:549:17)
    at processTimers (internal/timers.js:492:7)
name: "ClusterClientNoResponseError"
pid: 16165
hostname: localhost

2020-10-03 03:07:28,098 ERROR 16165 nodejs.ClusterClientNoResponseError: client no response in 575081ms exceeding maxIdleTime 60000ms, maybe the connection is close on other side.
    at Timeout._onTimeout (/Users/lxd/Desktop/mine/egg-example/node_modules/cluster-client/lib/leader.js:77:23)
    at listOnTimeout (internal/timers.js:549:17)
    at processTimers (internal/timers.js:492:7)
name: "ClusterClientNoResponseError"
pid: 16165
hostname: localhost

2020-10-03 03:17:43,186 ERROR 16165 nodejs.ClusterClientNoResponseError: client no response in 575081ms exceeding maxIdleTime 60000ms, maybe the connection is close on other side.
    at Timeout._onTimeout (/Users/lxd/Desktop/mine/egg-example/node_modules/cluster-client/lib/leader.js:77:23)
    at listOnTimeout (internal/timers.js:549:17)
    at processTimers (internal/timers.js:492:7)
name: "ClusterClientNoResponseError"
pid: 16165
hostname: localhost

2020-10-03 03:27:39,251 ERROR 16165 nodejs.ClusterClientNoResponseError: client no response in 576056ms exceeding maxIdleTime 60000ms, maybe the connection is close on other side.
    at Timeout._onTimeout (/Users/lxd/Desktop/mine/egg-example/node_modules/cluster-client/lib/leader.js:77:23)
    at listOnTimeout (internal/timers.js:549:17)
    at processTimers (internal/timers.js:492:7)
name: "ClusterClientNoResponseError"
pid: 16165
hostname: localhost

2020-10-03 03:37:57,345 ERROR 16165 nodejs.ClusterClientNoResponseError: client no response in 578083ms exceeding maxIdleTime 60000ms, maybe the connection is close on other side.
    at Timeout._onTimeout (/Users/lxd/Desktop/mine/egg-example/node_modules/cluster-client/lib/leader.js:77:23)
    at listOnTimeout (internal/timers.js:549:17)
    at processTimers (internal/timers.js:492:7)
name: "ClusterClientNoResponseError"
pid: 16165
hostname: localhost

2020-10-03 03:48:12,466 ERROR 16165 nodejs.ClusterClientNoResponseError: client no response in 575102ms exceeding maxIdleTime 60000ms, maybe the connection is close on other side.
    at Timeout._onTimeout (/Users/lxd/Desktop/mine/egg-example/node_modules/cluster-client/lib/leader.js:77:23)
    at listOnTimeout (internal/timers.js:549:17)
    at processTimers (internal/timers.js:492:7)
name: "ClusterClientNoResponseError"
pid: 16165
hostname: localhost

2020-10-03 03:58:08,536 ERROR 16165 nodejs.ClusterClientNoResponseError: client no response in 576063ms exceeding maxIdleTime 60000ms, maybe the connection is close on other side.
    at Timeout._onTimeout (/Users/lxd/Desktop/mine/egg-example/node_modules/cluster-client/lib/leader.js:77:23)
    at listOnTimeout (internal/timers.js:549:17)
    at processTimers (internal/timers.js:492:7)
name: "ClusterClientNoResponseError"
pid: 16165
hostname: localhost

2020-10-03 04:08:23,634 ERROR 16165 nodejs.ClusterClientNoResponseError: client no response in 575075ms exceeding maxIdleTime 60000ms, maybe the connection is close on other side.
    at Timeout._onTimeout (/Users/lxd/Desktop/mine/egg-example/node_modules/cluster-client/lib/leader.js:77:23)
    at listOnTimeout (internal/timers.js:549:17)
    at processTimers (internal/timers.js:492:7)
name: "ClusterClientNoResponseError"
pid: 16165
hostname: localhost

2020-10-03 04:18:38,718 ERROR 16165 nodejs.ClusterClientNoResponseError: client no response in 575062ms exceeding maxIdleTime 60000ms, maybe the connection is close on other side.
    at Timeout._onTimeout (/Users/lxd/Desktop/mine/egg-example/node_modules/cluster-client/lib/leader.js:77:23)
    at listOnTimeout (internal/timers.js:549:17)
    at processTimers (internal/timers.js:492:7)
name: "ClusterClientNoResponseError"
pid: 16165
hostname: localhost

2020-10-03 04:28:33,803 ERROR 16165 nodejs.ClusterClientNoResponseError: client no response in 575078ms exceeding maxIdleTime 60000ms, maybe the connection is close on other side.
    at Timeout._onTimeout (/Users/lxd/Desktop/mine/egg-example/node_modules/cluster-client/lib/leader.js:77:23)
    at listOnTimeout (internal/timers.js:549:17)
    at processTimers (internal/timers.js:492:7)
name: "ClusterClientNoResponseError"
pid: 16165
hostname: localhost

2020-10-03 04:38:49,901 ERROR 16165 nodejs.ClusterClientNoResponseError: client no response in 576081ms exceeding maxIdleTime 60000ms, maybe the connection is close on other side.
    at Timeout._onTimeout (/Users/lxd/Desktop/mine/egg-example/node_modules/cluster-client/lib/leader.js:77:23)
    at listOnTimeout (internal/timers.js:549:17)
    at processTimers (internal/timers.js:492:7)
name: "ClusterClientNoResponseError"
pid: 16165
hostname: localhost

2020-10-03 04:49:05,012 ERROR 16165 nodejs.ClusterClientNoResponseError: client no response in 575091ms exceeding maxIdleTime 60000ms, maybe the connection is close on other side.
    at Timeout._onTimeout (/Users/lxd/Desktop/mine/egg-example/node_modules/cluster-client/lib/leader.js:77:23)
    at listOnTimeout (internal/timers.js:549:17)
    at processTimers (internal/timers.js:492:7)
name: "ClusterClientNoResponseError"
pid: 16165
hostname: localhost

2020-10-03 04:59:00,099 ERROR 16165 nodejs.ClusterClientNoResponseError: client no response in 575080ms exceeding maxIdleTime 60000ms, maybe the connection is close on other side.
    at Timeout._onTimeout (/Users/lxd/Desktop/mine/egg-example/node_modules/cluster-client/lib/leader.js:77:23)
    at listOnTimeout (internal/timers.js:549:17)
    at processTimers (internal/timers.js:492:7)
name: "ClusterClientNoResponseError"
pid: 16165
hostname: localhost

2020-10-03 05:19:12,002 ERROR 16165 nodejs.ClusterClientNoResponseError: client no response in 576805ms exceeding maxIdleTime 60000ms, maybe the connection is close on other side.
    at Timeout._onTimeout (/Users/lxd/Desktop/mine/egg-example/node_modules/cluster-client/lib/leader.js:77:23)
    at listOnTimeout (internal/timers.js:549:17)
    at processTimers (internal/timers.js:492:7)
name: "ClusterClientNoResponseError"
pid: 16165
hostname: localhost

2020-10-03 05:29:27,100 ERROR 16165 nodejs.ClusterClientNoResponseError: client no response in 575088ms exceeding maxIdleTime 60000ms, maybe the connection is close on other side.
    at Timeout._onTimeout (/Users/lxd/Desktop/mine/egg-example/node_modules/cluster-client/lib/leader.js:77:23)
    at listOnTimeout (internal/timers.js:549:17)
    at processTimers (internal/timers.js:492:7)
name: "ClusterClientNoResponseError"
pid: 16165
hostname: localhost

2020-10-03 05:39:42,200 ERROR 16165 nodejs.ClusterClientNoResponseError: client no response in 575090ms exceeding maxIdleTime 60000ms, maybe the connection is close on other side.
    at Timeout._onTimeout (/Users/lxd/Desktop/mine/egg-example/node_modules/cluster-client/lib/leader.js:77:23)
    at listOnTimeout (internal/timers.js:549:17)
    at processTimers (internal/timers.js:492:7)
name: "ClusterClientNoResponseError"
pid: 16165
hostname: localhost

2020-10-03 05:49:37,290 ERROR 16165 nodejs.ClusterClientNoResponseError: client no response in 575081ms exceeding maxIdleTime 60000ms, maybe the connection is close on other side.
    at Timeout._onTimeout (/Users/lxd/Desktop/mine/egg-example/node_modules/cluster-client/lib/leader.js:77:23)
    at listOnTimeout (internal/timers.js:549:17)
    at processTimers (internal/timers.js:492:7)
name: "ClusterClientNoResponseError"
pid: 16165
hostname: localhost

2020-10-03 05:59:53,377 ERROR 16165 nodejs.ClusterClientNoResponseError: client no response in 576077ms exceeding maxIdleTime 60000ms, maybe the connection is close on other side.
    at Timeout._onTimeout (/Users/lxd/Desktop/mine/egg-example/node_modules/cluster-client/lib/leader.js:77:23)
    at listOnTimeout (internal/timers.js:549:17)
    at processTimers (internal/timers.js:492:7)
name: "ClusterClientNoResponseError"
pid: 16165
hostname: localhost

2020-10-03 06:10:08,464 ERROR 16165 nodejs.ClusterClientNoResponseError: client no response in 575073ms exceeding maxIdleTime 60000ms, maybe the connection is close on other side.
    at Timeout._onTimeout (/Users/lxd/Desktop/mine/egg-example/node_modules/cluster-client/lib/leader.js:77:23)
    at listOnTimeout (internal/timers.js:549:17)
    at processTimers (internal/timers.js:492:7)
name: "ClusterClientNoResponseError"
pid: 16165
hostname: localhost

2020-10-03 06:20:03,562 ERROR 16165 nodejs.ClusterClientNoResponseError: client no response in 575084ms exceeding maxIdleTime 60000ms, maybe the connection is close on other side.
    at Timeout._onTimeout (/Users/lxd/Desktop/mine/egg-example/node_modules/cluster-client/lib/leader.js:77:23)
    at listOnTimeout (internal/timers.js:549:17)
    at processTimers (internal/timers.js:492:7)
name: "ClusterClientNoResponseError"
pid: 16165
hostname: localhost

2020-10-03 06:30:19,650 ERROR 16165 nodejs.ClusterClientNoResponseError: client no response in 576071ms exceeding maxIdleTime 60000ms, maybe the connection is close on other side.
    at Timeout._onTimeout (/Users/lxd/Desktop/mine/egg-example/node_modules/cluster-client/lib/leader.js:77:23)
    at listOnTimeout (internal/timers.js:549:17)
    at processTimers (internal/timers.js:492:7)
name: "ClusterClientNoResponseError"
pid: 16165
hostname: localhost

2020-10-03 06:40:34,733 ERROR 16165 nodejs.ClusterClientNoResponseError: client no response in 575073ms exceeding maxIdleTime 60000ms, maybe the connection is close on other side.
    at Timeout._onTimeout (/Users/lxd/Desktop/mine/egg-example/node_modules/cluster-client/lib/leader.js:77:23)
    at listOnTimeout (internal/timers.js:549:17)
    at processTimers (internal/timers.js:492:7)
name: "ClusterClientNoResponseError"
pid: 16165
hostname: localhost

2020-10-03 06:50:29,828 ERROR 16165 nodejs.ClusterClientNoResponseError: client no response in 575084ms exceeding maxIdleTime 60000ms, maybe the connection is close on other side.
    at Timeout._onTimeout (/Users/lxd/Desktop/mine/egg-example/node_modules/cluster-client/lib/leader.js:77:23)
    at listOnTimeout (internal/timers.js:549:17)
    at processTimers (internal/timers.js:492:7)
name: "ClusterClientNoResponseError"
pid: 16165
hostname: localhost

2020-10-03 07:11:01,007 ERROR 16165 nodejs.ClusterClientNoResponseError: client no response in 575087ms exceeding maxIdleTime 60000ms, maybe the connection is close on other side.
    at Timeout._onTimeout (/Users/lxd/Desktop/mine/egg-example/node_modules/cluster-client/lib/leader.js:77:23)
    at listOnTimeout (internal/timers.js:549:17)
    at processTimers (internal/timers.js:492:7)
name: "ClusterClientNoResponseError"
pid: 16165
hostname: localhost

2020-10-03 07:20:56,098 ERROR 16165 nodejs.ClusterClientNoResponseError: client no response in 575079ms exceeding maxIdleTime 60000ms, maybe the connection is close on other side.
    at Timeout._onTimeout (/Users/lxd/Desktop/mine/egg-example/node_modules/cluster-client/lib/leader.js:77:23)
    at listOnTimeout (internal/timers.js:549:17)
    at processTimers (internal/timers.js:492:7)
name: "ClusterClientNoResponseError"
pid: 16165
hostname: localhost

2020-10-03 07:31:11,187 ERROR 16165 nodejs.ClusterClientNoResponseError: client no response in 575079ms exceeding maxIdleTime 60000ms, maybe the connection is close on other side.
    at Timeout._onTimeout (/Users/lxd/Desktop/mine/egg-example/node_modules/cluster-client/lib/leader.js:77:23)
    at listOnTimeout (internal/timers.js:549:17)
    at processTimers (internal/timers.js:492:7)
name: "ClusterClientNoResponseError"
pid: 16165
hostname: localhost

2020-10-03 07:41:07,268 ERROR 16165 nodejs.ClusterClientNoResponseError: client no response in 576072ms exceeding maxIdleTime 60000ms, maybe the connection is close on other side.
    at Timeout._onTimeout (/Users/lxd/Desktop/mine/egg-example/node_modules/cluster-client/lib/leader.js:77:23)
    at listOnTimeout (internal/timers.js:549:17)
    at processTimers (internal/timers.js:492:7)
name: "ClusterClientNoResponseError"
pid: 16165
hostname: localhost

2020-10-03 07:51:22,369 ERROR 16165 nodejs.ClusterClientNoResponseError: client no response in 575091ms exceeding maxIdleTime 60000ms, maybe the connection is close on other side.
    at Timeout._onTimeout (/Users/lxd/Desktop/mine/egg-example/node_modules/cluster-client/lib/leader.js:77:23)
    at listOnTimeout (internal/timers.js:549:17)
    at processTimers (internal/timers.js:492:7)
name: "ClusterClientNoResponseError"
pid: 16165
hostname: localhost

2020-10-03 08:01:37,464 ERROR 16165 nodejs.ClusterClientNoResponseError: client no response in 575075ms exceeding maxIdleTime 60000ms, maybe the connection is close on other side.
    at Timeout._onTimeout (/Users/lxd/Desktop/mine/egg-example/node_modules/cluster-client/lib/leader.js:77:23)
    at listOnTimeout (internal/timers.js:549:17)
    at processTimers (internal/timers.js:492:7)
name: "ClusterClientNoResponseError"
pid: 16165
hostname: localhost

2020-10-03 08:11:32,562 ERROR 16165 nodejs.ClusterClientNoResponseError: client no response in 575083ms exceeding maxIdleTime 60000ms, maybe the connection is close on other side.
    at Timeout._onTimeout (/Users/lxd/Desktop/mine/egg-example/node_modules/cluster-client/lib/leader.js:77:23)
    at listOnTimeout (internal/timers.js:549:17)
    at processTimers (internal/timers.js:492:7)
name: "ClusterClientNoResponseError"
pid: 16165
hostname: localhost

2020-10-03 08:21:48,659 ERROR 16165 nodejs.ClusterClientNoResponseError: client no response in 576085ms exceeding maxIdleTime 60000ms, maybe the connection is close on other side.
    at Timeout._onTimeout (/Users/lxd/Desktop/mine/egg-example/node_modules/cluster-client/lib/leader.js:77:23)
    at listOnTimeout (internal/timers.js:549:17)
    at processTimers (internal/timers.js:492:7)
name: "ClusterClientNoResponseError"
pid: 16165
hostname: localhost

2020-10-03 08:32:03,736 ERROR 16165 nodejs.ClusterClientNoResponseError: client no response in 575069ms exceeding maxIdleTime 60000ms, maybe the connection is close on other side.
    at Timeout._onTimeout (/Users/lxd/Desktop/mine/egg-example/node_modules/cluster-client/lib/leader.js:77:23)
    at listOnTimeout (internal/timers.js:549:17)
    at processTimers (internal/timers.js:492:7)
name: "ClusterClientNoResponseError"
pid: 16165
hostname: localhost

2020-10-03 08:41:58,819 ERROR 16165 nodejs.ClusterClientNoResponseError: client no response in 575076ms exceeding maxIdleTime 60000ms, maybe the connection is close on other side.
    at Timeout._onTimeout (/Users/lxd/Desktop/mine/egg-example/node_modules/cluster-client/lib/leader.js:77:23)
    at listOnTimeout (internal/timers.js:549:17)
    at processTimers (internal/timers.js:492:7)
name: "ClusterClientNoResponseError"
pid: 16165
hostname: localhost

2020-10-03 08:52:14,917 ERROR 16165 nodejs.ClusterClientNoResponseError: client no response in 576078ms exceeding maxIdleTime 60000ms, maybe the connection is close on other side.
    at Timeout._onTimeout (/Users/lxd/Desktop/mine/egg-example/node_modules/cluster-client/lib/leader.js:77:23)
    at listOnTimeout (internal/timers.js:549:17)
    at processTimers (internal/timers.js:492:7)
name: "ClusterClientNoResponseError"
pid: 16165
hostname: localhost

2020-10-03 09:02:30,006 ERROR 16165 nodejs.ClusterClientNoResponseError: client no response in 575074ms exceeding maxIdleTime 60000ms, maybe the connection is close on other side.
    at Timeout._onTimeout (/Users/lxd/Desktop/mine/egg-example/node_modules/cluster-client/lib/leader.js:77:23)
    at listOnTimeout (internal/timers.js:549:17)
    at processTimers (internal/timers.js:492:7)
name: "ClusterClientNoResponseError"
pid: 16165
hostname: localhost

2020-10-03 09:12:25,065 ERROR 16165 nodejs.ClusterClientNoResponseError: client no response in 575050ms exceeding maxIdleTime 60000ms, maybe the connection is close on other side.
    at Timeout._onTimeout (/Users/lxd/Desktop/mine/egg-example/node_modules/cluster-client/lib/leader.js:77:23)
    at listOnTimeout (internal/timers.js:549:17)
    at processTimers (internal/timers.js:492:7)
name: "ClusterClientNoResponseError"
pid: 16165
hostname: localhost

2020-10-03 09:20:49,155 ERROR 16165 nodejs.ClusterClientNoResponseError: client no response in 464080ms exceeding maxIdleTime 60000ms, maybe the connection is close on other side.
    at Timeout._onTimeout (/Users/lxd/Desktop/mine/egg-example/node_modules/cluster-client/lib/leader.js:77:23)
    at listOnTimeout (internal/timers.js:549:17)
    at processTimers (internal/timers.js:492:7)
name: "ClusterClientNoResponseError"
pid: 16165
hostname: localhost

2020-10-03 10:51:29,087 ERROR 24252 nodejs.ClusterClientNoResponseError: client no response in 573734ms exceeding maxIdleTime 60000ms, maybe the connection is close on other side.
    at Timeout._onTimeout (/Users/lxd/Desktop/mine/egg-example/node_modules/cluster-client/lib/leader.js:77:23)
    at listOnTimeout (internal/timers.js:549:17)
    at processTimers (internal/timers.js:492:7)
name: "ClusterClientNoResponseError"
pid: 24252
hostname: localhost

2020-10-03 11:01:45,159 ERROR 24252 nodejs.ClusterClientNoResponseError: client no response in 576055ms exceeding maxIdleTime 60000ms, maybe the connection is close on other side.
    at Timeout._onTimeout (/Users/lxd/Desktop/mine/egg-example/node_modules/cluster-client/lib/leader.js:77:23)
    at listOnTimeout (internal/timers.js:549:17)
    at processTimers (internal/timers.js:492:7)
name: "ClusterClientNoResponseError"
pid: 24252
hostname: localhost

2020-10-03 11:11:40,144 ERROR 24252 nodejs.ClusterClientNoResponseError: client no response in 574979ms exceeding maxIdleTime 60000ms, maybe the connection is close on other side.
    at Timeout._onTimeout (/Users/lxd/Desktop/mine/egg-example/node_modules/cluster-client/lib/leader.js:77:23)
    at listOnTimeout (internal/timers.js:549:17)
    at processTimers (internal/timers.js:492:7)
name: "ClusterClientNoResponseError"
pid: 24252
hostname: localhost

2020-10-03 11:21:56,108 ERROR 24252 nodejs.ClusterClientNoResponseError: client no response in 575948ms exceeding maxIdleTime 60000ms, maybe the connection is close on other side.
    at Timeout._onTimeout (/Users/lxd/Desktop/mine/egg-example/node_modules/cluster-client/lib/leader.js:77:23)
    at listOnTimeout (internal/timers.js:549:17)
    at processTimers (internal/timers.js:492:7)
name: "ClusterClientNoResponseError"
pid: 24252
hostname: localhost

2020-10-03 11:31:52,001 ERROR 24252 nodejs.ClusterClientNoResponseError: client no response in 575884ms exceeding maxIdleTime 60000ms, maybe the connection is close on other side.
    at Timeout._onTimeout (/Users/lxd/Desktop/mine/egg-example/node_modules/cluster-client/lib/leader.js:77:23)
    at listOnTimeout (internal/timers.js:549:17)
    at processTimers (internal/timers.js:492:7)
name: "ClusterClientNoResponseError"
pid: 24252
hostname: localhost

2020-10-03 11:42:06,993 ERROR 24252 nodejs.ClusterClientNoResponseError: client no response in 574967ms exceeding maxIdleTime 60000ms, maybe the connection is close on other side.
    at Timeout._onTimeout (/Users/lxd/Desktop/mine/egg-example/node_modules/cluster-client/lib/leader.js:77:23)
    at listOnTimeout (internal/timers.js:549:17)
    at processTimers (internal/timers.js:492:7)
name: "ClusterClientNoResponseError"
pid: 24252
hostname: localhost

2020-10-03 12:02:17,902 ERROR 24252 nodejs.ClusterClientNoResponseError: client no response in 574950ms exceeding maxIdleTime 60000ms, maybe the connection is close on other side.
    at Timeout._onTimeout (/Users/lxd/Desktop/mine/egg-example/node_modules/cluster-client/lib/leader.js:77:23)
    at listOnTimeout (internal/timers.js:549:17)
    at processTimers (internal/timers.js:492:7)
name: "ClusterClientNoResponseError"
pid: 24252
hostname: localhost

2020-10-03 12:12:33,893 ERROR 24252 nodejs.ClusterClientNoResponseError: client no response in 575979ms exceeding maxIdleTime 60000ms, maybe the connection is close on other side.
    at Timeout._onTimeout (/Users/lxd/Desktop/mine/egg-example/node_modules/cluster-client/lib/leader.js:77:23)
    at listOnTimeout (internal/timers.js:549:17)
    at processTimers (internal/timers.js:492:7)
name: "ClusterClientNoResponseError"
pid: 24252
hostname: localhost

2020-10-03 12:22:48,857 ERROR 24252 nodejs.ClusterClientNoResponseError: client no response in 574942ms exceeding maxIdleTime 60000ms, maybe the connection is close on other side.
    at Timeout._onTimeout (/Users/lxd/Desktop/mine/egg-example/node_modules/cluster-client/lib/leader.js:77:23)
    at listOnTimeout (internal/timers.js:549:17)
    at processTimers (internal/timers.js:492:7)
name: "ClusterClientNoResponseError"
pid: 24252
hostname: localhost

2020-10-03 12:32:43,825 ERROR 24252 nodejs.ClusterClientNoResponseError: client no response in 574957ms exceeding maxIdleTime 60000ms, maybe the connection is close on other side.
    at Timeout._onTimeout (/Users/lxd/Desktop/mine/egg-example/node_modules/cluster-client/lib/leader.js:77:23)
    at listOnTimeout (internal/timers.js:549:17)
    at processTimers (internal/timers.js:492:7)
name: "ClusterClientNoResponseError"
pid: 24252
hostname: localhost

2020-10-03 12:35:34,800 ERROR 24252 nodejs.ClusterClientNoResponseError: client no response in 130963ms exceeding maxIdleTime 60000ms, maybe the connection is close on other side.
    at Timeout._onTimeout (/Users/lxd/Desktop/mine/egg-example/node_modules/cluster-client/lib/leader.js:77:23)
    at listOnTimeout (internal/timers.js:549:17)
    at processTimers (internal/timers.js:492:7)
name: "ClusterClientNoResponseError"
pid: 24252
hostname: localhost

2020-10-03 13:01:00,997 ERROR 24252 nodejs.ClusterClientNoResponseError: client no response in 345959ms exceeding maxIdleTime 60000ms, maybe the connection is close on other side.
    at Timeout._onTimeout (/Users/lxd/Desktop/mine/egg-example/node_modules/cluster-client/lib/leader.js:77:23)
    at listOnTimeout (internal/timers.js:549:17)
    at processTimers (internal/timers.js:492:7)
name: "ClusterClientNoResponseError"
pid: 24252
hostname: localhost

2020-10-03 13:51:15,174 ERROR 24252 nodejs.ClusterClientNoResponseError: client no response in 259439ms exceeding maxIdleTime 60000ms, maybe the connection is close on other side.
    at Timeout._onTimeout (/Users/lxd/Desktop/mine/egg-example/node_modules/cluster-client/lib/leader.js:77:23)
    at listOnTimeout (internal/timers.js:549:17)
    at processTimers (internal/timers.js:492:7)
name: "ClusterClientNoResponseError"
pid: 24252
hostname: localhost

2020-10-03 14:45:31,583 ERROR 24252 nodejs.ClusterClientNoResponseError: client no response in 575772ms exceeding maxIdleTime 60000ms, maybe the connection is close on other side.
    at Timeout._onTimeout (/Users/lxd/Desktop/mine/egg-example/node_modules/cluster-client/lib/leader.js:77:23)
    at listOnTimeout (internal/timers.js:549:17)
    at processTimers (internal/timers.js:492:7)
name: "ClusterClientNoResponseError"
pid: 24252
hostname: localhost

2020-10-03 14:55:47,070 ERROR 24252 nodejs.ClusterClientNoResponseError: client no response in 575474ms exceeding maxIdleTime 60000ms, maybe the connection is close on other side.
    at Timeout._onTimeout (/Users/lxd/Desktop/mine/egg-example/node_modules/cluster-client/lib/leader.js:77:23)
    at listOnTimeout (internal/timers.js:549:17)
    at processTimers (internal/timers.js:492:7)
name: "ClusterClientNoResponseError"
pid: 24252
hostname: localhost

2020-10-03 15:06:02,021 ERROR 24252 nodejs.ClusterClientNoResponseError: client no response in 574937ms exceeding maxIdleTime 60000ms, maybe the connection is close on other side.
    at Timeout._onTimeout (/Users/lxd/Desktop/mine/egg-example/node_modules/cluster-client/lib/leader.js:77:23)
    at listOnTimeout (internal/timers.js:549:17)
    at processTimers (internal/timers.js:492:7)
name: "ClusterClientNoResponseError"
pid: 24252
hostname: localhost

2020-10-03 15:15:57,987 ERROR 24252 nodejs.ClusterClientNoResponseError: client no response in 575952ms exceeding maxIdleTime 60000ms, maybe the connection is close on other side.
    at Timeout._onTimeout (/Users/lxd/Desktop/mine/egg-example/node_modules/cluster-client/lib/leader.js:77:23)
    at listOnTimeout (internal/timers.js:549:17)
    at processTimers (internal/timers.js:492:7)
name: "ClusterClientNoResponseError"
pid: 24252
hostname: localhost

2020-10-03 15:26:12,952 ERROR 24252 nodejs.ClusterClientNoResponseError: client no response in 574950ms exceeding maxIdleTime 60000ms, maybe the connection is close on other side.
    at Timeout._onTimeout (/Users/lxd/Desktop/mine/egg-example/node_modules/cluster-client/lib/leader.js:77:23)
    at listOnTimeout (internal/timers.js:549:17)
    at processTimers (internal/timers.js:492:7)
name: "ClusterClientNoResponseError"
pid: 24252
hostname: localhost

2020-10-03 15:46:23,900 ERROR 24252 nodejs.ClusterClientNoResponseError: client no response in 574960ms exceeding maxIdleTime 60000ms, maybe the connection is close on other side.
    at Timeout._onTimeout (/Users/lxd/Desktop/mine/egg-example/node_modules/cluster-client/lib/leader.js:77:23)
    at listOnTimeout (internal/timers.js:549:17)
    at processTimers (internal/timers.js:492:7)
name: "ClusterClientNoResponseError"
pid: 24252
hostname: localhost

2020-10-03 15:56:39,837 ERROR 24252 nodejs.ClusterClientNoResponseError: client no response in 575919ms exceeding maxIdleTime 60000ms, maybe the connection is close on other side.
    at Timeout._onTimeout (/Users/lxd/Desktop/mine/egg-example/node_modules/cluster-client/lib/leader.js:77:23)
    at listOnTimeout (internal/timers.js:549:17)
    at processTimers (internal/timers.js:492:7)
name: "ClusterClientNoResponseError"
pid: 24252
hostname: localhost

2020-10-03 16:06:36,002 ERROR 24252 nodejs.ClusterClientNoResponseError: client no response in 576150ms exceeding maxIdleTime 60000ms, maybe the connection is close on other side.
    at Timeout._onTimeout (/Users/lxd/Desktop/mine/egg-example/node_modules/cluster-client/lib/leader.js:77:23)
    at listOnTimeout (internal/timers.js:549:17)
    at processTimers (internal/timers.js:492:7)
name: "ClusterClientNoResponseError"
pid: 24252
hostname: localhost

2020-10-03 16:16:50,982 ERROR 24252 nodejs.ClusterClientNoResponseError: client no response in 574959ms exceeding maxIdleTime 60000ms, maybe the connection is close on other side.
    at Timeout._onTimeout (/Users/lxd/Desktop/mine/egg-example/node_modules/cluster-client/lib/leader.js:77:23)
    at listOnTimeout (internal/timers.js:549:17)
    at processTimers (internal/timers.js:492:7)
name: "ClusterClientNoResponseError"
pid: 24252
hostname: localhost

2020-10-03 16:23:46,944 ERROR 24252 nodejs.ClusterClientNoResponseError: client no response in 375951ms exceeding maxIdleTime 60000ms, maybe the connection is close on other side.
    at Timeout._onTimeout (/Users/lxd/Desktop/mine/egg-example/node_modules/cluster-client/lib/leader.js:77:23)
    at listOnTimeout (internal/timers.js:549:17)
    at processTimers (internal/timers.js:492:7)
name: "ClusterClientNoResponseError"
pid: 24252
hostname: localhost

2020-10-03 16:27:44,983 ERROR 24252 nodejs.ClusterClientNoResponseError: client no response in 138005ms exceeding maxIdleTime 60000ms, maybe the connection is close on other side.
    at Timeout._onTimeout (/Users/lxd/Desktop/mine/egg-example/node_modules/cluster-client/lib/leader.js:77:23)
    at listOnTimeout (internal/timers.js:549:17)
    at processTimers (internal/timers.js:492:7)
name: "ClusterClientNoResponseError"
pid: 24252
hostname: localhost

2020-10-03 21:14:36,929 ERROR 24252 nodejs.ClusterClientNoResponseError: client no response in 194176ms exceeding maxIdleTime 60000ms, maybe the connection is close on other side.
    at Timeout._onTimeout (/Users/lxd/Desktop/mine/egg-example/node_modules/cluster-client/lib/leader.js:77:23)
    at listOnTimeout (internal/timers.js:549:17)
    at processTimers (internal/timers.js:492:7)
name: "ClusterClientNoResponseError"
pid: 24252
hostname: localhost

2020-10-04 09:53:31,033 ERROR 24252 nodejs.ClusterClientNoResponseError: client no response in 43273624ms exceeding maxIdleTime 60000ms, maybe the connection is close on other side.
    at Timeout._onTimeout (/Users/lxd/Desktop/mine/egg-example/node_modules/cluster-client/lib/leader.js:77:23)
    at listOnTimeout (internal/timers.js:549:17)
    at processTimers (internal/timers.js:492:7)
name: "ClusterClientNoResponseError"
pid: 24252
hostname: localhost

2020-10-04 10:28:17,227 ERROR 24252 nodejs.ClusterClientNoResponseError: client no response in 2066187ms exceeding maxIdleTime 60000ms, maybe the connection is close on other side.
    at Timeout._onTimeout (/Users/lxd/Desktop/mine/egg-example/node_modules/cluster-client/lib/leader.js:77:23)
    at listOnTimeout (internal/timers.js:549:17)
    at processTimers (internal/timers.js:492:7)
name: "ClusterClientNoResponseError"
pid: 24252
hostname: localhost

2020-10-04 10:45:11,603 ERROR 24252 nodejs.ClusterClientNoResponseError: client no response in 574336ms exceeding maxIdleTime 60000ms, maybe the connection is close on other side.
    at Timeout._onTimeout (/Users/lxd/Desktop/mine/egg-example/node_modules/cluster-client/lib/leader.js:77:23)
    at listOnTimeout (internal/timers.js:549:17)
    at processTimers (internal/timers.js:492:7)
name: "ClusterClientNoResponseError"
pid: 24252
hostname: localhost

2020-10-04 10:55:07,647 ERROR 24252 nodejs.ClusterClientNoResponseError: client no response in 576031ms exceeding maxIdleTime 60000ms, maybe the connection is close on other side.
    at Timeout._onTimeout (/Users/lxd/Desktop/mine/egg-example/node_modules/cluster-client/lib/leader.js:77:23)
    at listOnTimeout (internal/timers.js:549:17)
    at processTimers (internal/timers.js:492:7)
name: "ClusterClientNoResponseError"
pid: 24252
hostname: localhost

2020-10-04 11:05:02,749 ERROR 24252 nodejs.ClusterClientNoResponseError: client no response in 575090ms exceeding maxIdleTime 60000ms, maybe the connection is close on other side.
    at Timeout._onTimeout (/Users/lxd/Desktop/mine/egg-example/node_modules/cluster-client/lib/leader.js:77:23)
    at listOnTimeout (internal/timers.js:549:17)
    at processTimers (internal/timers.js:492:7)
name: "ClusterClientNoResponseError"
pid: 24252
hostname: localhost

2020-10-04 11:14:57,031 ERROR 24252 nodejs.ClusterClientNoResponseError: client no response in 574268ms exceeding maxIdleTime 60000ms, maybe the connection is close on other side.
    at Timeout._onTimeout (/Users/lxd/Desktop/mine/egg-example/node_modules/cluster-client/lib/leader.js:77:23)
    at listOnTimeout (internal/timers.js:549:17)
    at processTimers (internal/timers.js:492:7)
name: "ClusterClientNoResponseError"
pid: 24252
hostname: localhost

2020-10-04 11:35:08,366 ERROR 24252 nodejs.ClusterClientNoResponseError: client no response in 575824ms exceeding maxIdleTime 60000ms, maybe the connection is close on other side.
    at Timeout._onTimeout (/Users/lxd/Desktop/mine/egg-example/node_modules/cluster-client/lib/leader.js:77:23)
    at listOnTimeout (internal/timers.js:549:17)
    at processTimers (internal/timers.js:492:7)
name: "ClusterClientNoResponseError"
pid: 24252
hostname: localhost

2020-10-04 11:45:23,367 ERROR 24252 nodejs.ClusterClientNoResponseError: client no response in 574988ms exceeding maxIdleTime 60000ms, maybe the connection is close on other side.
    at Timeout._onTimeout (/Users/lxd/Desktop/mine/egg-example/node_modules/cluster-client/lib/leader.js:77:23)
    at listOnTimeout (internal/timers.js:549:17)
    at processTimers (internal/timers.js:492:7)
name: "ClusterClientNoResponseError"
pid: 24252
hostname: localhost

2020-10-04 11:55:21,790 ERROR 24252 nodejs.ClusterClientNoResponseError: client no response in 578413ms exceeding maxIdleTime 60000ms, maybe the connection is close on other side.
    at Timeout._onTimeout (/Users/lxd/Desktop/mine/egg-example/node_modules/cluster-client/lib/leader.js:77:23)
    at listOnTimeout (internal/timers.js:549:17)
    at processTimers (internal/timers.js:492:7)
name: "ClusterClientNoResponseError"
pid: 24252
hostname: localhost

2020-10-04 12:05:18,002 ERROR 24252 nodejs.ClusterClientNoResponseError: client no response in 576202ms exceeding maxIdleTime 60000ms, maybe the connection is close on other side.
    at Timeout._onTimeout (/Users/lxd/Desktop/mine/egg-example/node_modules/cluster-client/lib/leader.js:77:23)
    at listOnTimeout (internal/timers.js:549:17)
    at processTimers (internal/timers.js:492:7)
name: "ClusterClientNoResponseError"
pid: 24252
hostname: localhost

2020-10-04 12:25:28,820 ERROR 24252 nodejs.ClusterClientNoResponseError: client no response in 575308ms exceeding maxIdleTime 60000ms, maybe the connection is close on other side.
    at Timeout._onTimeout (/Users/lxd/Desktop/mine/egg-example/node_modules/cluster-client/lib/leader.js:77:23)
    at listOnTimeout (internal/timers.js:549:17)
    at processTimers (internal/timers.js:492:7)
name: "ClusterClientNoResponseError"
pid: 24252
hostname: localhost

2020-10-04 12:35:44,241 ERROR 24252 nodejs.ClusterClientNoResponseError: client no response in 575408ms exceeding maxIdleTime 60000ms, maybe the connection is close on other side.
    at Timeout._onTimeout (/Users/lxd/Desktop/mine/egg-example/node_modules/cluster-client/lib/leader.js:77:23)
    at listOnTimeout (internal/timers.js:549:17)
    at processTimers (internal/timers.js:492:7)
name: "ClusterClientNoResponseError"
pid: 24252
hostname: localhost

2020-10-04 12:45:40,445 ERROR 24252 nodejs.ClusterClientNoResponseError: client no response in 576200ms exceeding maxIdleTime 60000ms, maybe the connection is close on other side.
    at Timeout._onTimeout (/Users/lxd/Desktop/mine/egg-example/node_modules/cluster-client/lib/leader.js:77:23)
    at listOnTimeout (internal/timers.js:549:17)
    at processTimers (internal/timers.js:492:7)
name: "ClusterClientNoResponseError"
pid: 24252
hostname: localhost

2020-10-04 12:55:54,967 ERROR 24252 nodejs.ClusterClientNoResponseError: client no response in 574507ms exceeding maxIdleTime 60000ms, maybe the connection is close on other side.
    at Timeout._onTimeout (/Users/lxd/Desktop/mine/egg-example/node_modules/cluster-client/lib/leader.js:77:23)
    at listOnTimeout (internal/timers.js:549:17)
    at processTimers (internal/timers.js:492:7)
name: "ClusterClientNoResponseError"
pid: 24252
hostname: localhost

2020-10-04 13:05:50,388 ERROR 24252 nodejs.ClusterClientNoResponseError: client no response in 575411ms exceeding maxIdleTime 60000ms, maybe the connection is close on other side.
    at Timeout._onTimeout (/Users/lxd/Desktop/mine/egg-example/node_modules/cluster-client/lib/leader.js:77:23)
    at listOnTimeout (internal/timers.js:549:17)
    at processTimers (internal/timers.js:492:7)
name: "ClusterClientNoResponseError"
pid: 24252
hostname: localhost

2020-10-04 13:16:06,101 ERROR 24252 nodejs.ClusterClientNoResponseError: client no response in 575699ms exceeding maxIdleTime 60000ms, maybe the connection is close on other side.
    at Timeout._onTimeout (/Users/lxd/Desktop/mine/egg-example/node_modules/cluster-client/lib/leader.js:77:23)
    at listOnTimeout (internal/timers.js:549:17)
    at processTimers (internal/timers.js:492:7)
name: "ClusterClientNoResponseError"
pid: 24252
hostname: localhost

2020-10-04 13:26:01,403 ERROR 24252 nodejs.ClusterClientNoResponseError: client no response in 575295ms exceeding maxIdleTime 60000ms, maybe the connection is close on other side.
    at Timeout._onTimeout (/Users/lxd/Desktop/mine/egg-example/node_modules/cluster-client/lib/leader.js:77:23)
    at listOnTimeout (internal/timers.js:549:17)
    at processTimers (internal/timers.js:492:7)
name: "ClusterClientNoResponseError"
pid: 24252
hostname: localhost

2020-10-04 13:36:16,918 ERROR 24252 nodejs.ClusterClientNoResponseError: client no response in 575501ms exceeding maxIdleTime 60000ms, maybe the connection is close on other side.
    at Timeout._onTimeout (/Users/lxd/Desktop/mine/egg-example/node_modules/cluster-client/lib/leader.js:77:23)
    at listOnTimeout (internal/timers.js:549:17)
    at processTimers (internal/timers.js:492:7)
name: "ClusterClientNoResponseError"
pid: 24252
hostname: localhost

2020-10-04 13:51:19,074 ERROR 24252 nodejs.ClusterClientNoResponseError: client no response in 575699ms exceeding maxIdleTime 60000ms, maybe the connection is close on other side.
    at Timeout._onTimeout (/Users/lxd/Desktop/mine/egg-example/node_modules/cluster-client/lib/leader.js:77:23)
    at listOnTimeout (internal/timers.js:549:17)
    at processTimers (internal/timers.js:492:7)
name: "ClusterClientNoResponseError"
pid: 24252
hostname: localhost

2020-10-04 13:57:38,570 ERROR 24252 nodejs.ClusterClientNoResponseError: client no response in 359481ms exceeding maxIdleTime 60000ms, maybe the connection is close on other side.
    at Timeout._onTimeout (/Users/lxd/Desktop/mine/egg-example/node_modules/cluster-client/lib/leader.js:77:23)
    at listOnTimeout (internal/timers.js:549:17)
    at processTimers (internal/timers.js:492:7)
name: "ClusterClientNoResponseError"
pid: 24252
hostname: localhost

2020-10-04 17:37:43,667 ERROR 24252 nodejs.ClusterClientNoResponseError: client no response in 162354ms exceeding maxIdleTime 60000ms, maybe the connection is close on other side.
    at Timeout._onTimeout (/Users/lxd/Desktop/mine/egg-example/node_modules/cluster-client/lib/leader.js:77:23)
    at listOnTimeout (internal/timers.js:549:17)
    at processTimers (internal/timers.js:492:7)
name: "ClusterClientNoResponseError"
pid: 24252
hostname: localhost

2020-10-04 18:30:40,056 ERROR 24252 nodejs.ClusterClientNoResponseError: client no response in 295751ms exceeding maxIdleTime 60000ms, maybe the connection is close on other side.
    at Timeout._onTimeout (/Users/lxd/Desktop/mine/egg-example/node_modules/cluster-client/lib/leader.js:77:23)
    at listOnTimeout (internal/timers.js:549:17)
    at processTimers (internal/timers.js:492:7)
name: "ClusterClientNoResponseError"
pid: 24252
hostname: localhost

2020-10-04 19:27:03,831 ERROR 47132 [-/192.168.0.100/-/21ms POST /gannt/created] nodejs.SequelizeDatabaseError: Field 'type' doesn't have a default value
    at Query.formatError (/Users/lxd/Desktop/mine/egg-example/node_modules/sequelize/lib/dialects/mysql/query.js:239:16)
    at Query.run (/Users/lxd/Desktop/mine/egg-example/node_modules/sequelize/lib/dialects/mysql/query.js:54:18)
    at processTicksAndRejections (internal/process/task_queues.js:97:5)
name: "SequelizeDatabaseError"
parent: {"code":"ER_NO_DEFAULT_FOR_FIELD","errno":1364,"sqlState":"HY000","sqlMessage":"Field 'type' doesn't have a default value","sql":"INSERT INTO `gannt` (`id`,`label`,`user`) VALUES (?,?,?);","parameters":["4","4","4"]}
original: {"code":"ER_NO_DEFAULT_FOR_FIELD","errno":1364,"sqlState":"HY000","sqlMessage":"Field 'type' doesn't have a default value","sql":"INSERT INTO `gannt` (`id`,`label`,`user`) VALUES (?,?,?);","parameters":["4","4","4"]}
sql: "INSERT INTO `gannt` (`id`,`label`,`user`) VALUES (?,?,?);"
parameters: ["4","4","4"]
headers: {"Access-Control-Allow-Origin":"*","vary":"Origin"}
pid: 47132
hostname: localhost

2020-10-04 19:27:36,177 ERROR 47132 [-/192.168.0.100/-/5ms POST /gannt/created] nodejs.SequelizeDatabaseError: Field 'type' doesn't have a default value
    at Query.formatError (/Users/lxd/Desktop/mine/egg-example/node_modules/sequelize/lib/dialects/mysql/query.js:239:16)
    at Query.run (/Users/lxd/Desktop/mine/egg-example/node_modules/sequelize/lib/dialects/mysql/query.js:54:18)
    at processTicksAndRejections (internal/process/task_queues.js:97:5)
name: "SequelizeDatabaseError"
parent: {"code":"ER_NO_DEFAULT_FOR_FIELD","errno":1364,"sqlState":"HY000","sqlMessage":"Field 'type' doesn't have a default value","sql":"INSERT INTO `gannt` (`id`,`label`,`user`,`start`,`endDate`,`percent`,`proType`,`risk`) VALUES (?,?,?,?,?,?,?,?);","parameters":["4","4","4","2020-10-04 00-00-00","2020-10-05 00-00-00","4","4","4"]}
original: {"code":"ER_NO_DEFAULT_FOR_FIELD","errno":1364,"sqlState":"HY000","sqlMessage":"Field 'type' doesn't have a default value","sql":"INSERT INTO `gannt` (`id`,`label`,`user`,`start`,`endDate`,`percent`,`proType`,`risk`) VALUES (?,?,?,?,?,?,?,?);","parameters":["4","4","4","2020-10-04 00-00-00","2020-10-05 00-00-00","4","4","4"]}
sql: "INSERT INTO `gannt` (`id`,`label`,`user`,`start`,`endDate`,`percent`,`proType`,`risk`) VALUES (?,?,?,?,?,?,?,?);"
parameters: ["4","4","4","2020-10-04 00-00-00","2020-10-05 00-00-00","4","4","4"]
headers: {"Access-Control-Allow-Origin":"*","vary":"Origin"}
pid: 47132
hostname: localhost

2020-10-04 19:35:34,234 ERROR 47585 [-/192.168.0.100/-/17ms POST /gannt/update] nodejs.ReferenceError: params is not defined
    at GanntController.update (/Users/lxd/Desktop/mine/egg-example/app/controller/gannt.js:38:35)
    at processTicksAndRejections (internal/process/task_queues.js:97:5)
    at async /Users/lxd/Desktop/mine/egg-example/node_modules/egg-development/app/middleware/egg_loader_trace.js:9:50
    at async xframe (/Users/lxd/Desktop/mine/egg-example/node_modules/egg-security/lib/middlewares/xframe.js:7:5)
    at async xssProtection (/Users/lxd/Desktop/mine/egg-example/node_modules/egg-security/lib/middlewares/xssProtection.js:7:5)
    at async nosniff (/Users/lxd/Desktop/mine/egg-example/node_modules/egg-security/lib/middlewares/nosniff.js:8:5)
    at async noopen (/Users/lxd/Desktop/mine/egg-example/node_modules/egg-security/lib/middlewares/noopen.js:8:5)
    at async session (/Users/lxd/Desktop/mine/egg-example/node_modules/koa-session/index.js:41:7)
    at async bodyParser (/Users/lxd/Desktop/mine/egg-example/node_modules/koa-bodyparser/index.js:95:5)
    at async /Users/lxd/Desktop/mine/egg-example/node_modules/koa-static-cache/index.js:39:63
headers: {"Access-Control-Allow-Origin":"*","vary":"Origin"}
pid: 47585
hostname: localhost

2020-10-04 19:54:50,360 ERROR 47645 [-/192.168.0.100/-/6ms POST /gannt/created] nodejs.SequelizeUniqueConstraintError: Validation error
    at Query.formatError (/Users/lxd/Desktop/mine/egg-example/node_modules/sequelize/lib/dialects/mysql/query.js:218:16)
    at Query.run (/Users/lxd/Desktop/mine/egg-example/node_modules/sequelize/lib/dialects/mysql/query.js:54:18)
    at processTicksAndRejections (internal/process/task_queues.js:97:5)
name: "SequelizeUniqueConstraintError"
errors: [{"message":"gannt.PRIMARY must be unique","type":"unique violation","path":"gannt.PRIMARY","value":"1","origin":"DB","instance":{"id":1,"label":"5","user":"5","start":"2020-10-04 00-00-00","endDate":"2020-10-05 00-00-00","proType":"5","percent":"5","risk":"5"},"validatorKey":"not_unique","validatorName":null,"validatorArgs":[]}]
fields: {"gannt.PRIMARY":"1"}
parent: {"code":"ER_DUP_ENTRY","errno":1062,"sqlState":"23000","sqlMessage":"Duplicate entry '1' for key 'gannt.PRIMARY'","sql":"INSERT INTO `gannt` (`id`,`label`,`user`,`start`,`endDate`,`percent`,`proType`,`risk`) VALUES (?,?,?,?,?,?,?,?);","parameters":[1,"5","5","2020-10-04 00-00-00","2020-10-05 00-00-00","5","5","5"]}
original: {"code":"ER_DUP_ENTRY","errno":1062,"sqlState":"23000","sqlMessage":"Duplicate entry '1' for key 'gannt.PRIMARY'","sql":"INSERT INTO `gannt` (`id`,`label`,`user`,`start`,`endDate`,`percent`,`proType`,`risk`) VALUES (?,?,?,?,?,?,?,?);","parameters":[1,"5","5","2020-10-04 00-00-00","2020-10-05 00-00-00","5","5","5"]}
sql: "INSERT INTO `gannt` (`id`,`label`,`user`,`start`,`endDate`,`percent`,`proType`,`risk`) VALUES (?,?,?,?,?,?,?,?);"
headers: {"Access-Control-Allow-Origin":"*","vary":"Origin"}
pid: 47645
hostname: localhost

2020-10-04 19:54:51,389 ERROR 47645 [-/192.168.0.100/-/3ms POST /gannt/created] nodejs.SequelizeUniqueConstraintError: Validation error
    at Query.formatError (/Users/lxd/Desktop/mine/egg-example/node_modules/sequelize/lib/dialects/mysql/query.js:218:16)
    at Query.run (/Users/lxd/Desktop/mine/egg-example/node_modules/sequelize/lib/dialects/mysql/query.js:54:18)
    at processTicksAndRejections (internal/process/task_queues.js:97:5)
name: "SequelizeUniqueConstraintError"
errors: [{"message":"gannt.PRIMARY must be unique","type":"unique violation","path":"gannt.PRIMARY","value":"1","origin":"DB","instance":{"id":1,"label":"5","user":"5","start":"2020-10-04 00-00-00","endDate":"2020-10-05 00-00-00","proType":"5","percent":"5","risk":"5"},"validatorKey":"not_unique","validatorName":null,"validatorArgs":[]}]
fields: {"gannt.PRIMARY":"1"}
parent: {"code":"ER_DUP_ENTRY","errno":1062,"sqlState":"23000","sqlMessage":"Duplicate entry '1' for key 'gannt.PRIMARY'","sql":"INSERT INTO `gannt` (`id`,`label`,`user`,`start`,`endDate`,`percent`,`proType`,`risk`) VALUES (?,?,?,?,?,?,?,?);","parameters":[1,"5","5","2020-10-04 00-00-00","2020-10-05 00-00-00","5","5","5"]}
original: {"code":"ER_DUP_ENTRY","errno":1062,"sqlState":"23000","sqlMessage":"Duplicate entry '1' for key 'gannt.PRIMARY'","sql":"INSERT INTO `gannt` (`id`,`label`,`user`,`start`,`endDate`,`percent`,`proType`,`risk`) VALUES (?,?,?,?,?,?,?,?);","parameters":[1,"5","5","2020-10-04 00-00-00","2020-10-05 00-00-00","5","5","5"]}
sql: "INSERT INTO `gannt` (`id`,`label`,`user`,`start`,`endDate`,`percent`,`proType`,`risk`) VALUES (?,?,?,?,?,?,?,?);"
headers: {"Access-Control-Allow-Origin":"*","vary":"Origin"}
pid: 47645
hostname: localhost

2020-10-04 19:54:53,573 ERROR 47645 [-/192.168.0.100/-/3ms POST /gannt/created] nodejs.SequelizeUniqueConstraintError: Validation error
    at Query.formatError (/Users/lxd/Desktop/mine/egg-example/node_modules/sequelize/lib/dialects/mysql/query.js:218:16)
    at Query.run (/Users/lxd/Desktop/mine/egg-example/node_modules/sequelize/lib/dialects/mysql/query.js:54:18)
    at processTicksAndRejections (internal/process/task_queues.js:97:5)
name: "SequelizeUniqueConstraintError"
errors: [{"message":"gannt.PRIMARY must be unique","type":"unique violation","path":"gannt.PRIMARY","value":"1","origin":"DB","instance":{"id":1,"label":"5","user":"5","start":"2020-10-04 00-00-00","endDate":"2020-10-05 00-00-00","proType":"5","percent":"5","risk":"5"},"validatorKey":"not_unique","validatorName":null,"validatorArgs":[]}]
fields: {"gannt.PRIMARY":"1"}
parent: {"code":"ER_DUP_ENTRY","errno":1062,"sqlState":"23000","sqlMessage":"Duplicate entry '1' for key 'gannt.PRIMARY'","sql":"INSERT INTO `gannt` (`id`,`label`,`user`,`start`,`endDate`,`percent`,`proType`,`risk`) VALUES (?,?,?,?,?,?,?,?);","parameters":[1,"5","5","2020-10-04 00-00-00","2020-10-05 00-00-00","5","5","5"]}
original: {"code":"ER_DUP_ENTRY","errno":1062,"sqlState":"23000","sqlMessage":"Duplicate entry '1' for key 'gannt.PRIMARY'","sql":"INSERT INTO `gannt` (`id`,`label`,`user`,`start`,`endDate`,`percent`,`proType`,`risk`) VALUES (?,?,?,?,?,?,?,?);","parameters":[1,"5","5","2020-10-04 00-00-00","2020-10-05 00-00-00","5","5","5"]}
sql: "INSERT INTO `gannt` (`id`,`label`,`user`,`start`,`endDate`,`percent`,`proType`,`risk`) VALUES (?,?,?,?,?,?,?,?);"
headers: {"Access-Control-Allow-Origin":"*","vary":"Origin"}
pid: 47645
hostname: localhost

2020-10-04 19:55:25,692 ERROR 47645 [-/192.168.0.100/-/4ms POST /gannt/created] nodejs.SequelizeUniqueConstraintError: Validation error
    at Query.formatError (/Users/lxd/Desktop/mine/egg-example/node_modules/sequelize/lib/dialects/mysql/query.js:218:16)
    at Query.run (/Users/lxd/Desktop/mine/egg-example/node_modules/sequelize/lib/dialects/mysql/query.js:54:18)
    at processTicksAndRejections (internal/process/task_queues.js:97:5)
name: "SequelizeUniqueConstraintError"
errors: [{"message":"gannt.PRIMARY must be unique","type":"unique violation","path":"gannt.PRIMARY","value":"6","origin":"DB","instance":{"id":6,"label":"5","user":"5","start":"2020-10-04 00-00-00","endDate":"2020-10-05 00-00-00","proType":"5","percent":"5","risk":"5"},"validatorKey":"not_unique","validatorName":null,"validatorArgs":[]}]
fields: {"gannt.PRIMARY":"6"}
parent: {"code":"ER_DUP_ENTRY","errno":1062,"sqlState":"23000","sqlMessage":"Duplicate entry '6' for key 'gannt.PRIMARY'","sql":"INSERT INTO `gannt` (`id`,`label`,`user`,`start`,`endDate`,`percent`,`proType`,`risk`) VALUES (?,?,?,?,?,?,?,?);","parameters":[6,"5","5","2020-10-04 00-00-00","2020-10-05 00-00-00","5","5","5"]}
original: {"code":"ER_DUP_ENTRY","errno":1062,"sqlState":"23000","sqlMessage":"Duplicate entry '6' for key 'gannt.PRIMARY'","sql":"INSERT INTO `gannt` (`id`,`label`,`user`,`start`,`endDate`,`percent`,`proType`,`risk`) VALUES (?,?,?,?,?,?,?,?);","parameters":[6,"5","5","2020-10-04 00-00-00","2020-10-05 00-00-00","5","5","5"]}
sql: "INSERT INTO `gannt` (`id`,`label`,`user`,`start`,`endDate`,`percent`,`proType`,`risk`) VALUES (?,?,?,?,?,?,?,?);"
headers: {"Access-Control-Allow-Origin":"*","vary":"Origin"}
pid: 47645
hostname: localhost

2020-10-04 19:57:24,907 ERROR 47645 [-/192.168.0.100/-/8ms POST /gannt/created] nodejs.SequelizeUniqueConstraintError: Validation error
    at Query.formatError (/Users/lxd/Desktop/mine/egg-example/node_modules/sequelize/lib/dialects/mysql/query.js:218:16)
    at Query.run (/Users/lxd/Desktop/mine/egg-example/node_modules/sequelize/lib/dialects/mysql/query.js:54:18)
    at processTicksAndRejections (internal/process/task_queues.js:97:5)
name: "SequelizeUniqueConstraintError"
errors: [{"message":"gannt.PRIMARY must be unique","type":"unique violation","path":"gannt.PRIMARY","value":"9","origin":"DB","instance":{"id":9,"label":"5","user":"5","start":"2020-10-04 00-00-00","endDate":"2020-10-05 00-00-00","proType":"5","percent":"5","risk":"5"},"validatorKey":"not_unique","validatorName":null,"validatorArgs":[]}]
fields: {"gannt.PRIMARY":"9"}
parent: {"code":"ER_DUP_ENTRY","errno":1062,"sqlState":"23000","sqlMessage":"Duplicate entry '9' for key 'gannt.PRIMARY'","sql":"INSERT INTO `gannt` (`id`,`label`,`user`,`start`,`endDate`,`percent`,`proType`,`risk`) VALUES (?,?,?,?,?,?,?,?);","parameters":[9,"5","5","2020-10-04 00-00-00","2020-10-05 00-00-00","5","5","5"]}
original: {"code":"ER_DUP_ENTRY","errno":1062,"sqlState":"23000","sqlMessage":"Duplicate entry '9' for key 'gannt.PRIMARY'","sql":"INSERT INTO `gannt` (`id`,`label`,`user`,`start`,`endDate`,`percent`,`proType`,`risk`) VALUES (?,?,?,?,?,?,?,?);","parameters":[9,"5","5","2020-10-04 00-00-00","2020-10-05 00-00-00","5","5","5"]}
sql: "INSERT INTO `gannt` (`id`,`label`,`user`,`start`,`endDate`,`percent`,`proType`,`risk`) VALUES (?,?,?,?,?,?,?,?);"
headers: {"Access-Control-Allow-Origin":"*","vary":"Origin"}
pid: 47645
hostname: localhost

2020-10-05 04:06:28,003 ERROR 47128 nodejs.ClusterClientNoResponseError: client no response in 576184ms exceeding maxIdleTime 60000ms, maybe the connection is close on other side.
    at Timeout._onTimeout (/Users/lxd/Desktop/mine/egg-example/node_modules/cluster-client/lib/leader.js:77:23)
    at listOnTimeout (internal/timers.js:549:17)
    at processTimers (internal/timers.js:492:7)
name: "ClusterClientNoResponseError"
pid: 47128
hostname: localhost

2020-10-05 04:26:38,926 ERROR 47128 nodejs.ClusterClientNoResponseError: client no response in 575497ms exceeding maxIdleTime 60000ms, maybe the connection is close on other side.
    at Timeout._onTimeout (/Users/lxd/Desktop/mine/egg-example/node_modules/cluster-client/lib/leader.js:77:23)
    at listOnTimeout (internal/timers.js:549:17)
    at processTimers (internal/timers.js:492:7)
name: "ClusterClientNoResponseError"
pid: 47128
hostname: localhost

2020-10-05 04:36:54,454 ERROR 47128 nodejs.ClusterClientNoResponseError: client no response in 575513ms exceeding maxIdleTime 60000ms, maybe the connection is close on other side.
    at Timeout._onTimeout (/Users/lxd/Desktop/mine/egg-example/node_modules/cluster-client/lib/leader.js:77:23)
    at listOnTimeout (internal/timers.js:549:17)
    at processTimers (internal/timers.js:492:7)
name: "ClusterClientNoResponseError"
pid: 47128
hostname: localhost

2020-10-05 04:46:49,973 ERROR 47128 nodejs.ClusterClientNoResponseError: client no response in 575510ms exceeding maxIdleTime 60000ms, maybe the connection is close on other side.
    at Timeout._onTimeout (/Users/lxd/Desktop/mine/egg-example/node_modules/cluster-client/lib/leader.js:77:23)
    at listOnTimeout (internal/timers.js:549:17)
    at processTimers (internal/timers.js:492:7)
name: "ClusterClientNoResponseError"
pid: 47128
hostname: localhost

2020-10-05 05:07:01,095 ERROR 47128 nodejs.ClusterClientNoResponseError: client no response in 575504ms exceeding maxIdleTime 60000ms, maybe the connection is close on other side.
    at Timeout._onTimeout (/Users/lxd/Desktop/mine/egg-example/node_modules/cluster-client/lib/leader.js:77:23)
    at listOnTimeout (internal/timers.js:549:17)
    at processTimers (internal/timers.js:492:7)
name: "ClusterClientNoResponseError"
pid: 47128
hostname: localhost

2020-10-05 05:27:10,932 ERROR 47128 nodejs.ClusterClientNoResponseError: client no response in 574437ms exceeding maxIdleTime 60000ms, maybe the connection is close on other side.
    at Timeout._onTimeout (/Users/lxd/Desktop/mine/egg-example/node_modules/cluster-client/lib/leader.js:77:23)
    at listOnTimeout (internal/timers.js:549:17)
    at processTimers (internal/timers.js:492:7)
name: "ClusterClientNoResponseError"
pid: 47128
hostname: localhost

2020-10-05 05:37:26,854 ERROR 47128 nodejs.ClusterClientNoResponseError: client no response in 575903ms exceeding maxIdleTime 60000ms, maybe the connection is close on other side.
    at Timeout._onTimeout (/Users/lxd/Desktop/mine/egg-example/node_modules/cluster-client/lib/leader.js:77:23)
    at listOnTimeout (internal/timers.js:549:17)
    at processTimers (internal/timers.js:492:7)
name: "ClusterClientNoResponseError"
pid: 47128
hostname: localhost

2020-10-05 05:47:22,251 ERROR 47128 nodejs.ClusterClientNoResponseError: client no response in 575387ms exceeding maxIdleTime 60000ms, maybe the connection is close on other side.
    at Timeout._onTimeout (/Users/lxd/Desktop/mine/egg-example/node_modules/cluster-client/lib/leader.js:77:23)
    at listOnTimeout (internal/timers.js:549:17)
    at processTimers (internal/timers.js:492:7)
name: "ClusterClientNoResponseError"
pid: 47128
hostname: localhost

2020-10-05 05:57:37,876 ERROR 47128 nodejs.ClusterClientNoResponseError: client no response in 575602ms exceeding maxIdleTime 60000ms, maybe the connection is close on other side.
    at Timeout._onTimeout (/Users/lxd/Desktop/mine/egg-example/node_modules/cluster-client/lib/leader.js:77:23)
    at listOnTimeout (internal/timers.js:549:17)
    at processTimers (internal/timers.js:492:7)
name: "ClusterClientNoResponseError"
pid: 47128
hostname: localhost

2020-10-05 06:07:33,132 ERROR 47128 nodejs.ClusterClientNoResponseError: client no response in 575244ms exceeding maxIdleTime 60000ms, maybe the connection is close on other side.
    at Timeout._onTimeout (/Users/lxd/Desktop/mine/egg-example/node_modules/cluster-client/lib/leader.js:77:23)
    at listOnTimeout (internal/timers.js:549:17)
    at processTimers (internal/timers.js:492:7)
name: "ClusterClientNoResponseError"
pid: 47128
hostname: localhost

2020-10-05 06:17:48,294 ERROR 47128 nodejs.ClusterClientNoResponseError: client no response in 575149ms exceeding maxIdleTime 60000ms, maybe the connection is close on other side.
    at Timeout._onTimeout (/Users/lxd/Desktop/mine/egg-example/node_modules/cluster-client/lib/leader.js:77:23)
    at listOnTimeout (internal/timers.js:549:17)
    at processTimers (internal/timers.js:492:7)
name: "ClusterClientNoResponseError"
pid: 47128
hostname: localhost

2020-10-05 06:27:43,827 ERROR 47128 nodejs.ClusterClientNoResponseError: client no response in 575521ms exceeding maxIdleTime 60000ms, maybe the connection is close on other side.
    at Timeout._onTimeout (/Users/lxd/Desktop/mine/egg-example/node_modules/cluster-client/lib/leader.js:77:23)
    at listOnTimeout (internal/timers.js:549:17)
    at processTimers (internal/timers.js:492:7)
name: "ClusterClientNoResponseError"
pid: 47128
hostname: localhost

2020-10-05 06:38:00,328 ERROR 47128 nodejs.ClusterClientNoResponseError: client no response in 576488ms exceeding maxIdleTime 60000ms, maybe the connection is close on other side.
    at Timeout._onTimeout (/Users/lxd/Desktop/mine/egg-example/node_modules/cluster-client/lib/leader.js:77:23)
    at listOnTimeout (internal/timers.js:549:17)
    at processTimers (internal/timers.js:492:7)
name: "ClusterClientNoResponseError"
pid: 47128
hostname: localhost

2020-10-05 06:47:57,736 ERROR 47128 nodejs.ClusterClientNoResponseError: client no response in 577395ms exceeding maxIdleTime 60000ms, maybe the connection is close on other side.
    at Timeout._onTimeout (/Users/lxd/Desktop/mine/egg-example/node_modules/cluster-client/lib/leader.js:77:23)
    at listOnTimeout (internal/timers.js:549:17)
    at processTimers (internal/timers.js:492:7)
name: "ClusterClientNoResponseError"
pid: 47128
hostname: localhost

2020-10-05 06:57:54,001 ERROR 47128 nodejs.ClusterClientNoResponseError: client no response in 576259ms exceeding maxIdleTime 60000ms, maybe the connection is close on other side.
    at Timeout._onTimeout (/Users/lxd/Desktop/mine/egg-example/node_modules/cluster-client/lib/leader.js:77:23)
    at listOnTimeout (internal/timers.js:549:17)
    at processTimers (internal/timers.js:492:7)
name: "ClusterClientNoResponseError"
pid: 47128
hostname: localhost

2020-10-05 07:08:09,409 ERROR 47128 nodejs.ClusterClientNoResponseError: client no response in 575398ms exceeding maxIdleTime 60000ms, maybe the connection is close on other side.
    at Timeout._onTimeout (/Users/lxd/Desktop/mine/egg-example/node_modules/cluster-client/lib/leader.js:77:23)
    at listOnTimeout (internal/timers.js:549:17)
    at processTimers (internal/timers.js:492:7)
name: "ClusterClientNoResponseError"
pid: 47128
hostname: localhost

2020-10-05 07:18:04,732 ERROR 47128 nodejs.ClusterClientNoResponseError: client no response in 575313ms exceeding maxIdleTime 60000ms, maybe the connection is close on other side.
    at Timeout._onTimeout (/Users/lxd/Desktop/mine/egg-example/node_modules/cluster-client/lib/leader.js:77:23)
    at listOnTimeout (internal/timers.js:549:17)
    at processTimers (internal/timers.js:492:7)
name: "ClusterClientNoResponseError"
pid: 47128
hostname: localhost

2020-10-05 07:28:20,369 ERROR 47128 nodejs.ClusterClientNoResponseError: client no response in 575618ms exceeding maxIdleTime 60000ms, maybe the connection is close on other side.
    at Timeout._onTimeout (/Users/lxd/Desktop/mine/egg-example/node_modules/cluster-client/lib/leader.js:77:23)
    at listOnTimeout (internal/timers.js:549:17)
    at processTimers (internal/timers.js:492:7)
name: "ClusterClientNoResponseError"
pid: 47128
hostname: localhost

2020-10-05 07:38:16,070 ERROR 47128 nodejs.ClusterClientNoResponseError: client no response in 575691ms exceeding maxIdleTime 60000ms, maybe the connection is close on other side.
    at Timeout._onTimeout (/Users/lxd/Desktop/mine/egg-example/node_modules/cluster-client/lib/leader.js:77:23)
    at listOnTimeout (internal/timers.js:549:17)
    at processTimers (internal/timers.js:492:7)
name: "ClusterClientNoResponseError"
pid: 47128
hostname: localhost

2020-10-05 07:48:30,994 ERROR 47128 nodejs.ClusterClientNoResponseError: client no response in 574909ms exceeding maxIdleTime 60000ms, maybe the connection is close on other side.
    at Timeout._onTimeout (/Users/lxd/Desktop/mine/egg-example/node_modules/cluster-client/lib/leader.js:77:23)
    at listOnTimeout (internal/timers.js:549:17)
    at processTimers (internal/timers.js:492:7)
name: "ClusterClientNoResponseError"
pid: 47128
hostname: localhost

2020-10-05 07:58:25,617 ERROR 47128 nodejs.ClusterClientNoResponseError: client no response in 574611ms exceeding maxIdleTime 60000ms, maybe the connection is close on other side.
    at Timeout._onTimeout (/Users/lxd/Desktop/mine/egg-example/node_modules/cluster-client/lib/leader.js:77:23)
    at listOnTimeout (internal/timers.js:549:17)
    at processTimers (internal/timers.js:492:7)
name: "ClusterClientNoResponseError"
pid: 47128
hostname: localhost

2020-10-05 08:08:40,935 ERROR 47128 nodejs.ClusterClientNoResponseError: client no response in 575301ms exceeding maxIdleTime 60000ms, maybe the connection is close on other side.
    at Timeout._onTimeout (/Users/lxd/Desktop/mine/egg-example/node_modules/cluster-client/lib/leader.js:77:23)
    at listOnTimeout (internal/timers.js:549:17)
    at processTimers (internal/timers.js:492:7)
name: "ClusterClientNoResponseError"
pid: 47128
hostname: localhost

2020-10-05 08:18:37,369 ERROR 47128 nodejs.ClusterClientNoResponseError: client no response in 576426ms exceeding maxIdleTime 60000ms, maybe the connection is close on other side.
    at Timeout._onTimeout (/Users/lxd/Desktop/mine/egg-example/node_modules/cluster-client/lib/leader.js:77:23)
    at listOnTimeout (internal/timers.js:549:17)
    at processTimers (internal/timers.js:492:7)
name: "ClusterClientNoResponseError"
pid: 47128
hostname: localhost

2020-10-05 08:28:52,678 ERROR 47128 nodejs.ClusterClientNoResponseError: client no response in 575296ms exceeding maxIdleTime 60000ms, maybe the connection is close on other side.
    at Timeout._onTimeout (/Users/lxd/Desktop/mine/egg-example/node_modules/cluster-client/lib/leader.js:77:23)
    at listOnTimeout (internal/timers.js:549:17)
    at processTimers (internal/timers.js:492:7)
name: "ClusterClientNoResponseError"
pid: 47128
hostname: localhost

2020-10-05 08:38:48,288 ERROR 47128 nodejs.ClusterClientNoResponseError: client no response in 575604ms exceeding maxIdleTime 60000ms, maybe the connection is close on other side.
    at Timeout._onTimeout (/Users/lxd/Desktop/mine/egg-example/node_modules/cluster-client/lib/leader.js:77:23)
    at listOnTimeout (internal/timers.js:549:17)
    at processTimers (internal/timers.js:492:7)
name: "ClusterClientNoResponseError"
pid: 47128
hostname: localhost

2020-10-05 08:46:33,737 ERROR 47128 nodejs.ClusterClientNoResponseError: client no response in 425434ms exceeding maxIdleTime 60000ms, maybe the connection is close on other side.
    at Timeout._onTimeout (/Users/lxd/Desktop/mine/egg-example/node_modules/cluster-client/lib/leader.js:77:23)
    at listOnTimeout (internal/timers.js:549:17)
    at processTimers (internal/timers.js:492:7)
name: "ClusterClientNoResponseError"
pid: 47128
hostname: localhost

